Workbook

Sheet Tong_quan
A1: KẾ HOẠCH TRUYỀN THÔNG CÓ HỖ TRỢ AI – NHÓM HỮU DUYÊN
A2: PharmaDash – Dashboard điều hành chuỗi nhà thuốc · Lịch bám theo kế hoạch dự án (file QLDA_PharmaDash_LichDuAn.xlsx, sheet NenLich)
A4: Thông tin chung
A5: Sản phẩm | B5: PharmaDash – Dashboard điều hành chuỗi nhà thuốc (khách hàng giả định: chuỗi Nhà thuốc Hữu Duyên, 2 chi nhánh) – Nhóm Hữu Duyên
A6: Thời gian | B6: 05/10/2026 – 31/12/2026: 13 tuần, 6 giai đoạn (Khởi động → Triển khai); go-live 29/12/2026 theo lịch đã nén
A7: Hình thức | B7: Lập kế hoạch và sản xuất nội dung MÔ PHỎNG – KHÔNG đăng thật lên các kênh. Bài “Đã đăng (mô phỏng)” = bản cuối đã duyệt + ảnh xem trước (preview), lưu vào thư mục minh chứng.
A8: Kênh | B8: Facebook, TikTok/Reels, LinkedIn, YouTube (chi tiết ở sheet Kenh)
A9: Mục tiêu | B9: 1) Giới thiệu sản phẩm và tiến độ theo từng giai đoạn, bám 3 buổi demo với chủ nhà thuốc (30/10, 27/11, 23/12) và go-live 29/12. 2) Tạo minh chứng cá nhân: mỗi thành viên chuẩn bị 7–9 bài. 3) Thực hành dùng AI có kiểm soát: 100% bài có người kiểm tra và người duyệt trước giờ đăng.
A10: Đối tượng | B10: Giảng viên & hội đồng chấm; sinh viên CNTT, bạn cùng lớp; nhà tuyển dụng (LinkedIn); chủ, quản lý và dược sĩ nhà thuốc (người dùng giả định).
A11: Thông điệp chính | B11: Biết ngay lô thuốc nào sắp hết hạn, hàng nào sắp hết, doanh thu hôm nay bao nhiêu – trên một màn hình cho cả chuỗi nhà thuốc.
A12: Nguyên tắc dùng AI | B12: AI làm bản nháp (chữ, hình, phụ đề, giọng đọc); con người cung cấp dữ kiện, kiểm tra, sửa và chịu trách nhiệm. Không bài nào đi thẳng từ AI ra kênh (quy trình ở sheet Quy_trinh_AI).
A13: Vai trò chung | B13: Duyệt cuối: Nguyễn Mậu Thái Duy (PM) (bài do PM chuẩn bị thì Nguyễn Anh Dũng (BA) duyệt). Kiểm tra nội dung: Nguyễn Thị Thu Huyền (QA) kiểm bài của BA/BE/FE; Nguyễn Anh Dũng (BA) kiểm bài của PM/QA.
A14: Chi phí | B14: 0 đ cho quảng cáo (không đăng thật, không chạy ads). Công cụ AI ưu tiên gói miễn phí/tài khoản sẵn có; nếu cần trả phí thì báo PM và lấy từ khoản công cụ của dự án.
A16: Trụ cột nội dung
A17: Trụ cột | B17: Mô tả | E17: Số bài | F17: Tỷ trọng
A18: Hậu trường dự án | B18: Kick-off, họp tiến độ tuần, recap, đào tạo, go-live: cho thấy nhóm quản lý dự án như thế nào. | E18: =COUNTIF(Lich_dang!$J$5:$J$43,A18) -> 9 | F18: =IF(SUM($E$18:$E$22)=0,0,E18/SUM($E$18:$E$22)) -> 0.23076923
A19: Tính năng sản phẩm | B19: Giới thiệu từng tính năng ĐÃ làm xong: phân quyền 3 vai trò, Tổng quan, Kho thuốc theo lô, cảnh báo hạn dùng, nhập hàng, báo cáo. | E19: =COUNTIF(Lich_dang!$J$5:$J$43,A19) -> 9 | F19: =IF(SUM($E$18:$E$22)=0,0,E19/SUM($E$18:$E$22)) -> 0.23076923
A20: Kiến thức nghiệp vụ | B20: Bài toán của nhà thuốc: thuốc hết hạn, tồn kho theo lô, nguyên tắc FEFO, báo cáo thủ công, KPI kinh doanh. | E20: =COUNTIF(Lich_dang!$J$5:$J$43,A20) -> 6 | F20: =IF(SUM($E$18:$E$22)=0,0,E20/SUM($E$18:$E$22)) -> 0.15384615
A21: Kỹ thuật & quy trình | B21: PERT, quản lý rủi ro, CSDL, GitHub, chuyển đổi dữ liệu, kiểm thử: nội dung chuyên môn cho LinkedIn/TikTok. | E21: =COUNTIF(Lich_dang!$J$5:$J$43,A21) -> 10 | F21: =IF(SUM($E$18:$E$22)=0,0,E21/SUM($E$18:$E$22)) -> 0.25641026
A22: Sự kiện & demo | B22: Video giới thiệu (Demo 1), Demo 2, thư mời nghiệm thu, demo đầy đủ và go-live. | E22: =COUNTIF(Lich_dang!$J$5:$J$43,A22) -> 5 | F22: =IF(SUM($E$18:$E$22)=0,0,E22/SUM($E$18:$E$22)) -> 0.12820513
A23: Tổng | E23: =SUM(E18:E22) -> 39 | F23: =SUM(F18:F22) -> 1
A25: Lịch 13 tuần, mốc dự án và trọng tâm truyền thông
A26: Tuần | B26: Từ ngày | C26: Đến ngày | D26: Giai đoạn | E26: Mốc dự án (từ lịch dự án đã nén) | F26: Trọng tâm truyền thông
A27: 1 | B27: =DATE(2026,10,5) -> 46300 | C27: =DATE(2026,10,9) -> 46304 | D27: Khởi động | E27: 05/10 Kick-off; Charter, WBS, lịch, sổ rủi ro (WBS 1.1, 1.2) | F27: Ra mắt dự án, giới thiệu nhóm và bài toán nhà thuốc
A28: 2 | B28: =DATE(2026,10,12) -> 46307 | C28: =DATE(2026,10,16) -> 46311 | D28: Phân tích | E28: 12/10 xong kế hoạch; khảo sát 2 chi nhánh (WBS 2.1) | F28: Vấn đề của nhà thuốc: thuốc hết hạn, báo cáo thủ công
A29: 3 | B29: =DATE(2026,10,19) -> 46314 | C29: =DATE(2026,10,23) -> 46318 | D29: Phân tích | E29: 20/10 hạn kiểm tra kết nối phần mềm bán hàng (R01); bắt đầu SRS | F29: Kết quả khảo sát, rủi ro dữ liệu
A30: 4 | B30: =DATE(2026,10,26) -> 46321 | C30: =DATE(2026,10,30) -> 46325 | D30: Phân tích / Thiết kế | E30: 28/10 SRS được duyệt; 30/10 Demo 1 với chủ nhà thuốc | F30: User story, SRS; video giới thiệu dự án
A31: 5 | B31: =DATE(2026,11,2) -> 46328 | C31: =DATE(2026,11,6) -> 46332 | D31: Thiết kế | E31: 03/11 xong kiến trúc, CSDL; 05/11 xong mockup; test plan | F31: CSDL tồn kho theo lô, wireframe Dashboard
A32: 6 | B32: =DATE(2026,11,9) -> 46335 | C32: =DATE(2026,11,13) -> 46339 | D32: Phát triển | E32: 11/11 xong đăng nhập, phân quyền 3 vai trò; bắt đầu API, màn hình | F32: Phân quyền Chủ – Quản lý – Nhân viên; GitHub
A33: 7 | B33: =DATE(2026,11,16) -> 46342 | C33: =DATE(2026,11,20) -> 46346 | D33: Phát triển | E33: 17/11 xong khung giao diện, thư viện component | F33: Cảnh báo hạn dùng, component; recap giữa kỳ
A34: 8 | B34: =DATE(2026,11,23) -> 46349 | C34: =DATE(2026,11,27) -> 46353 | D34: Phát triển | E34: 27/11 xong tích hợp dữ liệu bán hàng, chuyển đổi dữ liệu; 27/11 Demo 2 | F34: Chuyển đổi dữ liệu, trang Tổng quan; video Demo 2
A35: 9 | B35: =DATE(2026,11,30) -> 46356 | C35: =DATE(2026,12,4) -> 46360 | D35: Phát triển / Kiểm thử | E35: 02/12 API, 03/12 màn hình, 04/12 xuất báo cáo; 30/11 bắt đầu kiểm thử | F35: Kho thuốc, nhập hàng; kiểm thử từ sớm
A36: 10 | B36: =DATE(2026,12,7) -> 46363 | C36: =DATE(2026,12,11) -> 46367 | D36: Kiểm thử | E36: Kiểm thử chức năng, phân quyền (WBS 6.2) | F36: Xuất báo cáo, thử phá phân quyền; bình chọn KPI
A37: 11 | B37: =DATE(2026,12,14) -> 46370 | C37: =DATE(2026,12,18) -> 46374 | D37: Kiểm thử | E37: 16/12 xong kiểm thử hệ thống, bắt đầu UAT | F37: Hiệu năng, hậu trường sửa lỗi; thư mời nghiệm thu
A38: 12 | B38: =DATE(2026,12,21) -> 46377 | C38: =DATE(2026,12,25) -> 46381 | D38: Nghiệm thu | E38: 23/12 xong UAT, Demo 3 (nghiệm thu); bắt đầu đào tạo | F38: Hướng dẫn sử dụng, demo đầy đủ, đào tạo
A39: 13 | B39: =DATE(2026,12,28) -> 46384 | C39: =DATE(2026,12,31) -> 46387 | D39: Triển khai | E39: 29/12 go-live; hỗ trợ sau go-live; tổng kết | F39: Go-live, highlight, tổng kết dự án
A41: Cách dùng các sheet
A42: Lich_dang | B42: Lịch 39 bài: ngày/giờ đăng, kênh, AI làm gì, công cụ, prompt, gói WBS, người chuẩn bị/kiểm tra/duyệt, hạn chót. Thành viên cập nhật các ô nền xanh lá.
A43: Quy_trinh_AI | B43: 7 bước từ brief → AI nháp → người sửa → duyệt → lưu minh chứng; phân vai AI/người; công cụ AI dùng cho việc gì.
A44: Prompt_mau | B44: Mẫu brief và 10 prompt mẫu (P01–P10) được tham chiếu trong cột Prompt của Lich_dang.
...

Sheet Lich_dang
A1: LỊCH ĐĂNG BÀI – 39 BÀI / 4 KÊNH / 13 TUẦN (MÔ PHỎNG, KHÔNG ĐĂNG THẬT)
A2: Ô nền xanh lá: thành viên cập nhật. Tuần, Giai đoạn, Thứ, Ngày làm nội dung, Hạn duyệt, Đúng hạn? tự tính. Prompt mẫu xem sheet Prompt_mau; checklist xem sheet Kiem_duyet.
A4: STT | B4: Mã bài | C4: Tuần | D4: Ngày đăng | E4: Thứ | F4: Giờ đăng | G4: Kênh | H4: Tiêu đề / chủ đề bài | I4: Giai đoạn | J4: Trụ cột nội dung | K4: Định dạng | L4: Nội dung chính & đầu vào cần chuẩn bị | M4: AI làm gì | N4: Công cụ AI | O4: Prompt mẫu | P4: Gắn với WBS / mốc | Q4: Người chuẩn bị (đầu vào + chạy AI) | R4: Người kiểm tra nội dung | S4: Người duyệt | T4: Ngày làm nội dung (D-2) | U4: Hạn duyệt (D-1) | V4: Ngày duyệt thực tế | W4: Đúng hạn? | X4: Qua checklist? | Y4: Trạng thái | Z4: Link bản nháp / minh chứng | AA4: Ghi chú
A5: 1 | B5: FB01 | C5: =MATCH(D5,Tong_quan!$B$27:$B$39,1) -> 1 | D5: =DATE(2026,10,7) -> 46302 | E5: =CHOOSE(WEEKDAY(D5),"CN","Thứ 2","Thứ 3","Thứ 4","Thứ 5","Thứ 6","Thứ 7") -> Thứ 4 | F5: 20:00 | G5: Facebook | H5: Nhóm Hữu Duyên khởi động dự án PharmaDash – Dashboard điều hành chuỗi nhà thuốc | I5: =INDEX(Tong_quan!$D$27:$D$39,C5) -> Khởi động | J5: Hậu trường dự án | K5: Ảnh bìa + caption | L5: Biên bản kick-off 05/10 (mục tiêu, phạm vi, vai trò); Project Charter; ảnh nhóm | M5: Viết 3 phương án caption từ biên bản kick-off; tạo ảnh bìa có tên dự án | N5: Claude/ChatGPT + Canva (AI) | O5: P01, P06 | P5: 1.1.1, 1.1.2 | Q5: Nguyễn Mậu Thái Duy (PM) | R5: Nguyễn Anh Dũng (BA) | S5: Nguyễn Anh Dũng (BA) | T5: =WORKDAY(D5,-2) -> 46300 | U5: =WORKDAY(D5,-1) -> 46301 | W5: =IF(V5="","",IF(V5<=U5,"Đúng hạn","Trễ")) | Y5: Chưa làm
A6: 2 | B6: LI01 | C6: =MATCH(D6,Tong_quan!$B$27:$B$39,1) -> 1 | D6: =DATE(2026,10,8) -> 46303 | E6: =CHOOSE(WEEKDAY(D6),"CN","Thứ 2","Thứ 3","Thứ 4","Thứ 5","Thứ 6","Thứ 7") -> Thứ 5 | F6: 08:00 | G6: LinkedIn | H6: 5 vai trò trong dự án PharmaDash và cách nhóm chia việc theo WBS | I6: =INDEX(Tong_quan!$D$27:$D$39,C6) -> Khởi động | J6: Hậu trường dự án | K6: Bài viết + sơ đồ vai trò | L6: Bảng phân vai PM/BA/BE/FE/QA; WBS 7 hạng mục, 47 gói công việc | M6: Viết nháp bài 150–250 từ; vẽ sơ đồ 5 vai trò; gợi ý hashtag | N6: Claude/ChatGPT + Canva (AI) | O6: P03, P07 | P6: 1.2.1 | Q6: Nguyễn Mậu Thái Duy (PM) | R6: Nguyễn Anh Dũng (BA) | S6: Nguyễn Anh Dũng (BA) | T6: =WORKDAY(D6,-2) -> 46301 | U6: =WORKDAY(D6,-1) -> 46302 | W6: =IF(V6="","",IF(V6<=U6,"Đúng hạn","Trễ")) | Y6: Chưa làm
A7: 3 | B7: TT01 | C7: =MATCH(D7,Tong_quan!$B$27:$B$39,1) -> 1 | D7: =DATE(2026,10,9) -> 46304 | E7: =CHOOSE(WEEKDAY(D7),"CN","Thứ 2","Thứ 3","Thứ 4","Thứ 5","Thứ 6","Thứ 7") -> Thứ 6 | F7: 19:00 | G7: TikTok/Reels | H7: Buổi kick-off PharmaDash trong 30 giây | I7: =INDEX(Tong_quan!$D$27:$D$39,C7) -> Khởi động | J7: Hậu trường dự án | K7: Video dọc 9:16, 30 giây | L7: 6–8 clip ngắn quay buổi kick-off/họp nhóm | M7: Viết kịch bản 30 giây (hook 3 giây đầu, chữ trên màn hình); tạo phụ đề tự động | N7: Claude/ChatGPT + CapCut | O7: P02, P08 | P7: 1.1.2 | Q7: Nguyễn Thị Thu Huyền (QA) | R7: Nguyễn Anh Dũng (BA) | S7: Nguyễn Mậu Thái Duy (PM) | T7: =WORKDAY(D7,-2) -> 46302 | U7: =WORKDAY(D7,-1) -> 46303 | W7: =IF(V7="","",IF(V7<=U7,"Đúng hạn","Trễ")) | Y7: Chưa làm | AA7: Xin phép thành viên trước khi dùng hình/giọng nói
A8: 4 | B8: FB02 | C8: =MATCH(D8,Tong_quan!$B$27:$B$39,1) -> 2 | D8: =DATE(2026,10,13) -> 46308 | E8: =CHOOSE(WEEKDAY(D8),"CN","Thứ 2","Thứ 3","Thứ 4","Thứ 5","Thứ 6","Thứ 7") -> Thứ 3 | F8: 20:00 | G8: Facebook | H8: Một năm hủy 45 triệu đồng thuốc hết hạn – vì sao nhà thuốc phát hiện muộn? | I8: =INDEX(Tong_quan!$D$27:$D$39,C8) -> Phân tích | J8: Kiến thức nghiệp vụ | K8: Carousel 5 slide | L8: Tài liệu yêu cầu khách hàng (mục A1); ghi chú phỏng vấn 2 chi nhánh (2.1.1) | M8: Tóm tắt khó khăn thành 5 ý cho 5 slide; dàn trang carousel | N8: Claude/ChatGPT + Canva (AI) | O8: P05, P10 | P8: 2.1.1 | Q8: Nguyễn Anh Dũng (BA) | R8: Nguyễn Thị Thu Huyền (QA) | S8: Nguyễn Mậu Thái Duy (PM) | T8: =WORKDAY(D8,-2) -> 46304 | U8: =WORKDAY(D8,-1) -> 46307 | W8: =IF(V8="","",IF(V8<=U8,"Đúng hạn","Trễ")) | Y8: Chưa làm | AA8: Ghi rõ đây là tình huống giả định của đồ án, không phải số liệu nhà thuốc thật
A9: 5 | B9: TT02 | C9: =MATCH(D9,Tong_quan!$B$27:$B$39,1) -> 2 | D9: =DATE(2026,10,15) -> 46310 | E9: =CHOOSE(WEEKDAY(D9),"CN","Thứ 2","Thứ 3","Thứ 4","Thứ 5","Thứ 6","Thứ 7") -> Thứ 5 | F9: 19:00 | G9: TikTok/Reels | H9: Một ngày ghi tồn kho bằng Excel ở 2 chi nhánh | I9: =INDEX(Tong_quan!$D$27:$D$39,C9) -> Phân tích | J9: Kiến thức nghiệp vụ | K9: Video dọc 9:16, 30 giây | L9: Ghi chú khảo sát (2.1.1, 2.1.2); clip dựng lại cảnh nhập Excel bằng dữ liệu giả | M9: Viết kịch bản dạng “trước khi có PharmaDash”; phụ đề | N9: Claude/ChatGPT + CapCut | O9: P02, P08 | P9: 2.1.1, 2.1.2 | Q9: Nguyễn Anh Dũng (BA) | R9: Nguyễn Thị Thu Huyền (QA) | S9: Nguyễn Mậu Thái Duy (PM) | T9: =WORKDAY(D9,-2) -> 46308 | U9: =WORKDAY(D9,-1) -> 46309 | W9: =IF(V9="","",IF(V9<=U9,"Đúng hạn","Trễ")) | Y9: Chưa làm | AA9: Không quay khách hàng, đơn thuốc hay quầy thuốc thật
A10: 6 | B10: LI02 | C10: =MATCH(D10,Tong_quan!$B$27:$B$39,1) -> 2 | D10: =DATE(2026,10,16) -> 46311 | E10: =CHOOSE(WEEKDAY(D10),"CN","Thứ 2","Thứ 3","Thứ 4","Thứ 5","Thứ 6","Thứ 7") -> Thứ 6 | F10: 08:00 | G10: LinkedIn | H10: Ước lượng lịch bằng PERT: vì sao kế hoạch đầu tiên của nhóm trễ 11 ngày | I10: =INDEX(Tong_quan!$D$27:$D$39,C10) -> Phân tích | J10: Kỹ thuật & quy trình | K10: Bài viết + ảnh Gantt | L10: Sheet PERT và NenLich trong file lịch dự án; đường găng, xác suất kịp hạn | M10: Viết nháp bài từ góc nhìn người lập lịch; gợi ý ảnh minh hoạ | N10: Claude/ChatGPT | O10: P03 | P10: 1.2.2 | Q10: Võ Thị Minh Thơ (FE) | R10: Nguyễn Thị Thu Huyền (QA) | S10: Nguyễn Mậu Thái Duy (PM) | T10: =WORKDAY(D10,-2) -> 46309 | U10: =WORKDAY(D10,-1) -> 46310 | W10: =IF(V10="","",IF(V10<=U10,"Đúng hạn","Trễ")) | Y10: Chưa làm
A11: 7 | B11: FB03 | C11: =MATCH(D11,Tong_quan!$B$27:$B$39,1) -> 3 | D11: =DATE(2026,10,20) -> 46315 | E11: =CHOOSE(WEEKDAY(D11),"CN","Thứ 2","Thứ 3","Thứ 4","Thứ 5","Thứ 6","Thứ 7") -> Thứ 3 | F11: 20:00 | G11: Facebook | H11: Khảo sát xong: 3 vấn đề lớn nhất của chuỗi nhà thuốc | I11: =INDEX(Tong_quan!$D$27:$D$39,C11) -> Phân tích | J11: Kiến thức nghiệp vụ | K11: Ảnh + caption | L11: Báo cáo khảo sát (2.1.1, 2.1.2) | M11: Viết caption từ báo cáo khảo sát; tự soát số liệu (P10) | N11: Claude/ChatGPT + Canva (AI) | O11: P01, P10 | P11: 2.1.1, 2.1.2 | Q11: Nguyễn Anh Dũng (BA) | R11: Nguyễn Thị Thu Huyền (QA) | S11: Nguyễn Mậu Thái Duy (PM) | T11: =WORKDAY(D11,-2) -> 46311 | U11: =WORKDAY(D11,-1) -> 46314 | W11: =IF(V11="","",IF(V11<=U11,"Đúng hạn","Trễ")) | Y11: Chưa làm
A12: 8 | B12: LI03 | C12: =MATCH(D12,Tong_quan!$B$27:$B$39,1) -> 3 | D12: =DATE(2026,10,21) -> 46316 | E12: =CHOOSE(WEEKDAY(D12),"CN","Thứ 2","Thứ 3","Thứ 4","Thứ 5","Thứ 6","Thứ 7") -> Thứ 4 | F12: 08:00 | G12: LinkedIn | H12: Quản lý rủi ro từ ngày đầu: sổ đăng ký 12 rủi ro của PharmaDash | I12: =INDEX(Tong_quan!$D$27:$D$39,C12) -> Phân tích | J12: Kỹ thuật & quy trình | K12: Bài viết + ảnh ma trận rủi ro | L12: Sheet RuiRo, MaTran; kế hoạch dự phòng R01 | M12: Viết nháp bài 150–250 từ; đề xuất 2–3 bài học | N12: Claude/ChatGPT | O12: P03 | P12: 1.2.3 | Q12: Nguyễn Thị Thu Huyền (QA) | R12: Nguyễn Anh Dũng (BA) | S12: Nguyễn Mậu Thái Duy (PM) | T12: =WORKDAY(D12,-2) -> 46314 | U12: =WORKDAY(D12,-1) -> 46315 | W12: =IF(V12="","",IF(V12<=U12,"Đúng hạn","Trễ")) | Y12: Chưa làm
A13: 9 | B13: TT03 | C13: =MATCH(D13,Tong_quan!$B$27:$B$39,1) -> 3 | D13: =DATE(2026,10,22) -> 46317 | E13: =CHOOSE(WEEKDAY(D13),"CN","Thứ 2","Thứ 3","Thứ 4","Thứ 5","Thứ 6","Thứ 7") -> Thứ 5 | F13: 19:00 | G13: TikTok/Reels | H13: Phần mềm bán hàng không có API thì lấy dữ liệu thế nào? | I13: =INDEX(Tong_quan!$D$27:$D$39,C13) -> Phân tích | J13: Kỹ thuật & quy trình | K13: Video dọc 9:16, 30–45 giây | L13: Kết quả kiểm tra kết nối phần mềm bán hàng (rủi ro R01, hạn 20/10); phương án nhập file | M13: Viết kịch bản giải thích 2 phương án (API / nhập file theo lịch); phụ đề | N13: Claude/ChatGPT + CapCut | O13: P02, P08 | P13: 2.1.2, 4.4.1 | Q13: Phan Hữu Vinh (BE) | R13: Nguyễn Thị Thu Huyền (QA) | S13: Nguyễn Mậu Thái Duy (PM) | T13: =WORKDAY(D13,-2) -> 46315 | U13: =WORKDAY(D13,-1) -> 46316 | W13: =IF(V13="","",IF(V13<=U13,"Đúng hạn","Trễ")) | Y13: Chưa làm | AA13: Không nêu tên phần mềm bán hàng thật
A14: 10 | B14: FB04 | C14: =MATCH(D14,Tong_quan!$B$27:$B$39,1) -> 4 | D14: =DATE(2026,10,27) -> 46322 | E14: =CHOOSE(WEEKDAY(D14),"CN","Thứ 2","Thứ 3","Thứ 4","Thứ 5","Thứ 6","Thứ 7") -> Thứ 3 | F14: 20:00 | G14: Facebook | H14: User story: “Là chủ nhà thuốc, tôi muốn biết lô nào sắp hết hạn” | I14: =INDEX(Tong_quan!$D$27:$D$39,C14) -> Phân tích / Thiết kế | J14: Kiến thức nghiệp vụ | K14: Carousel 5 slide | L14: Product backlog, tiêu chí chấp nhận (2.2.1) | M14: Chọn 5 user story tiêu biểu thành 5 slide | N14: Claude/ChatGPT + Canva (AI) | O14: P05 | P14: 2.2.1 | Q14: Nguyễn Anh Dũng (BA) | R14: Nguyễn Thị Thu Huyền (QA) | S14: Nguyễn Mậu Thái Duy (PM) | T14: =WORKDAY(D14,-2) -> 46318 | U14: =WORKDAY(D14,-1) -> 46321 | W14: =IF(V14="","",IF(V14<=U14,"Đúng hạn","Trễ")) | Y14: Chưa làm
A15: 11 | B15: FB05 | C15: =MATCH(D15,Tong_quan!$B$27:$B$39,1) -> 4 | D15: =DATE(2026,10,29) -> 46324 | E15: =CHOOSE(WEEKDAY(D15),"CN","Thứ 2","Thứ 3","Thứ 4","Thứ 5","Thứ 6","Thứ 7") -> Thứ 5 | F15: 20:00 | G15: Facebook | H15: SRS được duyệt: 8 yêu cầu bắt buộc FR01–FR08 | I15: =INDEX(Tong_quan!$D$27:$D$39,C15) -> Phân tích / Thiết kế | J15: Hậu trường dự án | K15: Infographic + caption | L15: SRS đã duyệt 28/10 (2.2.3); danh sách FR01–FR12 | M15: Thiết kế infographic 8 yêu cầu; viết caption | N15: Claude/ChatGPT + Canva (AI) | O15: P06, P01 | P15: 2.2.3 | Q15: Nguyễn Anh Dũng (BA) | R15: Nguyễn Thị Thu Huyền (QA) | S15: Nguyễn Mậu Thái Duy (PM) | T15: =WORKDAY(D15,-2) -> 46322 | U15: =WORKDAY(D15,-1) -> 46323 | W15: =IF(V15="","",IF(V15<=U15,"Đúng hạn","Trễ")) | Y15: Chưa làm
A16: 12 | B16: YT01 | C16: =MATCH(D16,Tong_quan!$B$27:$B$39,1) -> 4 | D16: =DATE(2026,10,30) -> 46325 | E16: =CHOOSE(WEEKDAY(D16),"CN","Thứ 2","Thứ 3","Thứ 4","Thứ 5","Thứ 6","Thứ 7") -> Thứ 6 | F16: 19:30 | G16: YouTube | H16: Giới thiệu dự án PharmaDash: vấn đề – giải pháp – lộ trình (Demo 1) | I16: =INDEX(Tong_quan!$D$27:$D$39,C16) -> Phân tích / Thiết kế | J16: Sự kiện & demo | K16: Video ngang 16:9, 4–6 phút | L16: Slide giới thiệu, wireframe, sơ đồ kiến trúc, clip nhóm; biên bản Demo 1 | M16: Viết kịch bản, tiêu đề, mô tả, chapters; phụ đề | N16: Claude/ChatGPT + CapCut | O16: P04, P07, P08 | P16: 1.3.2 | Q16: Nguyễn Mậu Thái Duy (PM) | R16: Nguyễn Anh Dũng (BA) | S16: Nguyễn Anh Dũng (BA) | T16: =WORKDAY(D16,-2) -> 46323 | U16: =WORKDAY(D16,-1) -> 46324 | W16: =IF(V16="","",IF(V16<=U16,"Đúng hạn","Trễ")) | Y16: Chưa làm
A17: 13 | B17: LI04 | C17: =MATCH(D17,Tong_quan!$B$27:$B$39,1) -> 5 | D17: =DATE(2026,11,3) -> 46329 | E17: =CHOOSE(WEEKDAY(D17),"CN","Thứ 2","Thứ 3","Thứ 4","Thứ 5","Thứ 6","Thứ 7") -> Thứ 3 | F17: 08:00 | G17: LinkedIn | H17: Thiết kế CSDL tồn kho theo lô: vì sao không chỉ lưu một cột “số lượng” | I17: =INDEX(Tong_quan!$D$27:$D$39,C17) -> Thiết kế | J17: Kỹ thuật & quy trình | K17: Bài viết + ERD | L17: ERD, script tạo CSDL (3.1.2); ghi chú khó khăn khi thiết kế | M17: Viết nháp bài; đề xuất 3 bài học về thiết kế dữ liệu | N17: Claude/ChatGPT | O17: P03 | P17: 3.1.2 | Q17: Phan Hữu Vinh (BE) | R17: Nguyễn Thị Thu Huyền (QA) | S17: Nguyễn Mậu Thái Duy (PM) | T17: =WORKDAY(D17,-2) -> 46325 | U17: =WORKDAY(D17,-1) -> 46328 | W17: =IF(V17="","",IF(V17<=U17,"Đúng hạn","Trễ")) | Y17: Chưa làm
A18: 14 | B18: FB06 | C18: =MATCH(D18,Tong_quan!$B$27:$B$39,1) -> 5 | D18: =DATE(2026,11,4) -> 46330 | E18: =CHOOSE(WEEKDAY(D18),"CN","Thứ 2","Thứ 3","Thứ 4","Thứ 5","Thứ 6","Thứ 7") -> Thứ 4 | F18: 20:00 | G18: Facebook | H18: Hé lộ wireframe Dashboard điều hành nhà thuốc | I18: =INDEX(Tong_quan!$D$27:$D$39,C18) -> Thiết kế | J18: Tính năng sản phẩm | K18: Ảnh mockup + caption | L18: Wireframe, mockup 8 màn hình (3.2.1, 3.2.2) | M18: Viết caption; dựng ảnh mockup trên khung máy tính | N18: Claude/ChatGPT + Canva (AI) | O18: P01, P06 | P18: 3.2.1, 3.2.2 | Q18: Võ Thị Minh Thơ (FE) | R18: Nguyễn Thị Thu Huyền (QA) | S18: Nguyễn Mậu Thái Duy (PM) | T18: =WORKDAY(D18,-2) -> 46328 | U18: =WORKDAY(D18,-1) -> 46329 | W18: =IF(V18="","",IF(V18<=U18,"Đúng hạn","Trễ")) | Y18: Chưa làm
A19: 15 | B19: TT04 | C19: =MATCH(D19,Tong_quan!$B$27:$B$39,1) -> 5 | D19: =DATE(2026,11,6) -> 46332 | E19: =CHOOSE(WEEKDAY(D19),"CN","Thứ 2","Thứ 3","Thứ 4","Thứ 5","Thứ 6","Thứ 7") -> Thứ 6 | F19: 19:00 | G19: TikTok/Reels | H19: Từ phác thảo đến giao diện: thiết kế Dashboard trong 30 giây | I19: =INDEX(Tong_quan!$D$27:$D$39,C19) -> Thiết kế | J19: Tính năng sản phẩm | K19: Video dọc 9:16, 30 giây | L19: File thiết kế, bảng màu, design token (3.2.1) | M19: Viết kịch bản “trước – sau”; phụ đề | N19: Claude/ChatGPT + CapCut | O19: P02, P08 | P19: 3.2.1, 3.2.2 | Q19: Võ Thị Minh Thơ (FE) | R19: Nguyễn Thị Thu Huyền (QA) | S19: Nguyễn Mậu Thái Duy (PM) | T19: =WORKDAY(D19,-2) -> 46330 | U19: =WORKDAY(D19,-1) -> 46331 | W19: =IF(V19="","",IF(V19<=U19,"Đúng hạn","Trễ")) | Y19: Chưa làm
A20: 16 | B20: FB07 | C20: =MATCH(D20,Tong_quan!$B$27:$B$39,1) -> 6 | D20: =DATE(2026,11,10) -> 46336 | E20: =CHOOSE(WEEKDAY(D20),"CN","Thứ 2","Thứ 3","Thứ 4","Thứ 5","Thứ 6","Thứ 7") -> Thứ 3 | F20: 20:00 | G20: Facebook | H20: Mỗi người chỉ thấy đúng phần việc của mình: phân quyền Chủ – Quản lý – Nhân viên | I20: =INDEX(Tong_quan!$D$27:$D$39,C20) -> Phát triển | J20: Tính năng sản phẩm | K20: Carousel 5 slide | L20: Mô tả xác thực và phân quyền (4.1.2); ảnh màn hình 3 vai trò (dữ liệu giả) | M20: Chuyển mô tả phân quyền thành 5 slide | N20: Claude/ChatGPT + Canva (AI) | O20: P05 | P20: 4.1.2 | Q20: Phan Hữu Vinh (BE) | R20: Nguyễn Thị Thu Huyền (QA) | S20: Nguyễn Mậu Thái Duy (PM) | T20: =WORKDAY(D20,-2) -> 46332 | U20: =WORKDAY(D20,-1) -> 46335 | W20: =IF(V20="","",IF(V20<=U20,"Đúng hạn","Trễ")) | Y20: Chưa làm
A21: 17 | B21: TT05 | C21: =MATCH(D21,Tong_quan!$B$27:$B$39,1) -> 6 | D21: =DATE(2026,11,12) -> 46338 | E21: =CHOOSE(WEEKDAY(D21),"CN","Thứ 2","Thứ 3","Thứ 4","Thứ 5","Thứ 6","Thứ 7") -> Thứ 5 | F21: 19:00 | G21: TikTok/Reels | H21: Đăng nhập bằng tài khoản nhân viên thì thấy gì? | I21: =INDEX(Tong_quan!$D$27:$D$39,C21) -> Phát triển | J21: Tính năng sản phẩm | K21: Video quay màn hình 9:16, 30 giây | L21: Clip đăng nhập 3 tài khoản demo, so sánh màn hình (4.1.2) | M21: Viết kịch bản; phụ đề | N21: Claude/ChatGPT + CapCut | O21: P02, P08 | P21: 4.1.2 | Q21: Võ Thị Minh Thơ (FE) | R21: Nguyễn Thị Thu Huyền (QA) | S21: Nguyễn Mậu Thái Duy (PM) | T21: =WORKDAY(D21,-2) -> 46336 | U21: =WORKDAY(D21,-1) -> 46337 | W21: =IF(V21="","",IF(V21<=U21,"Đúng hạn","Trễ")) | Y21: Chưa làm | AA21: Chỉ dùng tài khoản demo, dữ liệu giả
A22: 18 | B22: LI05 | C22: =MATCH(D22,Tong_quan!$B$27:$B$39,1) -> 6 | D22: =DATE(2026,11,13) -> 46339 | E22: =CHOOSE(WEEKDAY(D22),"CN","Thứ 2","Thứ 3","Thứ 4","Thứ 5","Thứ 6","Thứ 7") -> Thứ 6 | F22: 08:00 | G22: LinkedIn | H22: Làm việc nhóm với GitHub: commit nhỏ, đẩy code mỗi ngày | I22: =INDEX(Tong_quan!$D$27:$D$39,C22) -> Phát triển | J22: Kỹ thuật & quy trình | K22: Bài viết + ảnh lịch sử commit | L22: Lịch sử commit trên GitHub (4.1.1); quy ước “người đỡ” của rủi ro R11 | M22: Viết nháp bài; gợi ý ảnh minh hoạ | N22: Claude/ChatGPT | O22: P03 | P22: 4.1.1 | Q22: Phan Hữu Vinh (BE) | R22: Nguyễn Thị Thu Huyền (QA) | S22: Nguyễn Mậu Thái Duy (PM) | T22: =WORKDAY(D22,-2) -> 46337 | U22: =WORKDAY(D22,-1) -> 46338 | W22: =IF(V22="","",IF(V22<=U22,"Đúng hạn","Trễ")) | Y22: Chưa làm
A23: 19 | B23: FB08 | C23: =MATCH(D23,Tong_quan!$B$27:$B$39,1) -> 7 | D23: =DATE(2026,11,17) -> 46343 | E23: =CHOOSE(WEEKDAY(D23),"CN","Thứ 2","Thứ 3","Thứ 4","Thứ 5","Thứ 6","Thứ 7") -> Thứ 3 | F23: 20:00 | G23: Facebook | H23: Cảnh báo hạn dùng 30/60/90 ngày hoạt động thế nào? | I23: =INDEX(Tong_quan!$D$27:$D$39,C23) -> Phát triển | J23: Kiến thức nghiệp vụ | K23: Infographic + caption | L23: Quy tắc cảnh báo FR04; nguyên tắc xuất lô hết hạn trước (FEFO) (4.2.2) | M23: Thiết kế infographic 3 mức cảnh báo; viết caption | N23: Claude/ChatGPT + Canva (AI) | O23: P06, P01 | P23: 4.2.2 | Q23: Nguyễn Anh Dũng (BA) | R23: Nguyễn Thị Thu Huyền (QA) | S23: Nguyễn Mậu Thái Duy (PM) | T23: =WORKDAY(D23,-2) -> 46339 | U23: =WORKDAY(D23,-1) -> 46342 | W23: =IF(V23="","",IF(V23<=U23,"Đúng hạn","Trễ")) | Y23: Chưa làm
A24: 20 | B24: TT06 | C24: =MATCH(D24,Tong_quan!$B$27:$B$39,1) -> 7 | D24: =DATE(2026,11,18) -> 46344 | E24: =CHOOSE(WEEKDAY(D24),"CN","Thứ 2","Thứ 3","Thứ 4","Thứ 5","Thứ 6","Thứ 7") -> Thứ 4 | F24: 19:00 | G24: TikTok/Reels | H24: Thư viện component: một thẻ KPI dùng cho cả 4 chỉ số | I24: =INDEX(Tong_quan!$D$27:$D$39,C24) -> Phát triển | J24: Kỹ thuật & quy trình | K24: Video dọc 9:16, 30 giây | L24: Thư viện component (5.1.2); clip giao diện | M24: Viết kịch bản; phụ đề | N24: Claude/ChatGPT + CapCut | O24: P02, P08 | P24: 5.1.2 | Q24: Võ Thị Minh Thơ (FE) | R24: Nguyễn Thị Thu Huyền (QA) | S24: Nguyễn Mậu Thái Duy (PM) | T24: =WORKDAY(D24,-2) -> 46342 | U24: =WORKDAY(D24,-1) -> 46343 | W24: =IF(V24="","",IF(V24<=U24,"Đúng hạn","Trễ")) | Y24: Chưa làm
A25: 21 | B25: FB09 | C25: =MATCH(D25,Tong_quan!$B$27:$B$39,1) -> 7 | D25: =DATE(2026,11,20) -> 46346 | E25: =CHOOSE(WEEKDAY(D25),"CN","Thứ 2","Thứ 3","Thứ 4","Thứ 5","Thứ 6","Thứ 7") -> Thứ 6 | F25: 20:00 | G25: Facebook | H25: Recap giữa kỳ: đã xong gì, còn gì trước go-live | I25: =INDEX(Tong_quan!$D$27:$D$39,C25) -> Phát triển | J25: Hậu trường dự án | K25: Ảnh + caption | L25: Biên bản họp tiến độ tuần (1.3.1); file lịch dự án | M25: Tóm tắt biên bản thành bài recap 3 phần | N25: Claude/ChatGPT + Canva (AI) | O25: P09 | P25: 1.3.1 | Q25: Nguyễn Mậu Thái Duy (PM) | R25: Nguyễn Anh Dũng (BA) | S25: Nguyễn Anh Dũng (BA) | T25: =WORKDAY(D25,-2) -> 46344 | U25: =WORKDAY(D25,-1) -> 46345 | W25: =IF(V25="","",IF(V25<=U25,"Đúng hạn","Trễ")) | Y25: Chưa làm
A26: 22 | B26: LI06 | C26: =MATCH(D26,Tong_quan!$B$27:$B$39,1) -> 8 | D26: =DATE(2026,11,24) -> 46350 | E26: =CHOOSE(WEEKDAY(D26),"CN","Thứ 2","Thứ 3","Thứ 4","Thứ 5","Thứ 6","Thứ 7") -> Thứ 3 | F26: 08:00 | G26: LinkedIn | H26: Chuyển đổi 2 năm dữ liệu bán hàng từ Excel: 3 lỗi dữ liệu nhóm gặp | I26: =INDEX(Tong_quan!$D$27:$D$39,C26) -> Phát triển | J26: Kỹ thuật & quy trình | K26: Bài viết | L26: Script chuyển đổi, báo cáo đối soát (4.4.2) | M26: Viết nháp bài từ góc nhìn backend; đề xuất bài học | N26: Claude/ChatGPT | O26: P03 | P26: 4.4.2 | Q26: Phan Hữu Vinh (BE) | R26: Nguyễn Thị Thu Huyền (QA) | S26: Nguyễn Mậu Thái Duy (PM) | T26: =WORKDAY(D26,-2) -> 46346 | U26: =WORKDAY(D26,-1) -> 46349 | W26: =IF(V26="","",IF(V26<=U26,"Đúng hạn","Trễ")) | Y26: Chưa làm | AA26: Chỉ mô tả lỗi, không đưa dữ liệu thật
A27: 23 | B27: FB10 | C27: =MATCH(D27,Tong_quan!$B$27:$B$39,1) -> 8 | D27: =DATE(2026,11,25) -> 46351 | E27: =CHOOSE(WEEKDAY(D27),"CN","Thứ 2","Thứ 3","Thứ 4","Thứ 5","Thứ 6","Thứ 7") -> Thứ 4 | F27: 20:00 | G27: Facebook | H27: Hé lộ trang Tổng quan: doanh thu, đơn hàng, lợi nhuận trên một màn hình | I27: =INDEX(Tong_quan!$D$27:$D$39,C27) -> Phát triển | J27: Tính năng sản phẩm | K27: Ảnh màn hình + caption | L27: Ảnh trang Tổng quan (5.2.1) với dữ liệu mẫu | M27: Viết caption; làm mờ chỗ cần che | N27: Claude/ChatGPT + Canva (AI) | O27: P01 | P27: 5.2.1, 4.2.1 | Q27: Võ Thị Minh Thơ (FE) | R27: Nguyễn Thị Thu Huyền (QA) | S27: Nguyễn Mậu Thái Duy (PM) | T27: =WORKDAY(D27,-2) -> 46349 | U27: =WORKDAY(D27,-1) -> 46350 | W27: =IF(V27="","",IF(V27<=U27,"Đúng hạn","Trễ")) | Y27: Chưa làm
A28: 24 | B28: YT02 | C28: =MATCH(D28,Tong_quan!$B$27:$B$39,1) -> 8 | D28: =DATE(2026,11,27) -> 46353 | E28: =CHOOSE(WEEKDAY(D28),"CN","Thứ 2","Thứ 3","Thứ 4","Thứ 5","Thứ 6","Thứ 7") -> Thứ 6 | F28: 19:30 | G28: YouTube | H28: Demo 2: Tổng quan và Kho thuốc với dữ liệu mẫu (5–7 phút) | I28: =INDEX(Tong_quan!$D$27:$D$39,C28) -> Phát triển | J28: Sự kiện & demo | K28: Video ngang 16:9, 5–7 phút | L28: Quay màn hình 5.2.1, 5.2.2; kịch bản demo; biên bản Demo 2 | M28: Viết kịch bản demo, tiêu đề, mô tả, chapters; phụ đề | N28: Claude/ChatGPT + CapCut | O28: P04, P07, P08 | P28: 1.3.2, 5.2.1, 5.2.2 | Q28: Võ Thị Minh Thơ (FE) | R28: Nguyễn Thị Thu Huyền (QA) | S28: Nguyễn Mậu Thái Duy (PM) | T28: =WORKDAY(D28,-2) -> 46351 | U28: =WORKDAY(D28,-1) -> 46352 | W28: =IF(V28="","",IF(V28<=U28,"Đúng hạn","Trễ")) | Y28: Chưa làm
A29: 25 | B29: TT07 | C29: =MATCH(D29,Tong_quan!$B$27:$B$39,1) -> 9 | D29: =DATE(2026,12,1) -> 46357 | E29: =CHOOSE(WEEKDAY(D29),"CN","Thứ 2","Thứ 3","Thứ 4","Thứ 5","Thứ 6","Thứ 7") -> Thứ 3 | F29: 19:00 | G29: TikTok/Reels | H29: Tìm một lô thuốc sắp hết hạn giữa 1.200 mặt hàng | I29: =INDEX(Tong_quan!$D$27:$D$39,C29) -> Phát triển / Kiểm thử | J29: Tính năng sản phẩm | K29: Video quay màn hình 9:16, 30 giây | L29: Clip tab “Sắp hết hạn” và bộ lọc 30/60/90 ngày (5.2.2) | M29: Viết kịch bản; phụ đề | N29: Claude/ChatGPT + CapCut | O29: P02, P08 | P29: 5.2.2 | Q29: Võ Thị Minh Thơ (FE) | R29: Nguyễn Thị Thu Huyền (QA) | S29: Nguyễn Mậu Thái Duy (PM) | T29: =WORKDAY(D29,-2) -> 46353 | U29: =WORKDAY(D29,-1) -> 46356 | W29: =IF(V29="","",IF(V29<=U29,"Đúng hạn","Trễ")) | Y29: Chưa làm
A30: 26 | B30: FB11 | C30: =MATCH(D30,Tong_quan!$B$27:$B$39,1) -> 9 | D30: =DATE(2026,12,2) -> 46358 | E30: =CHOOSE(WEEKDAY(D30),"CN","Thứ 2","Thứ 3","Thứ 4","Thứ 5","Thứ 6","Thứ 7") -> Thứ 4 | F30: 20:00 | G30: Facebook | H30: Nhận hàng là tồn kho theo lô tự cập nhật | I30: =INDEX(Tong_quan!$D$27:$D$39,C30) -> Phát triển / Kiểm thử | J30: Tính năng sản phẩm | K30: Carousel 5 slide | L30: Luồng phiếu nhập: Nháp → Đã đặt → Nhận hàng (4.2.4, 5.2.4); ảnh màn hình | M30: Chuyển luồng nhập hàng thành 5 slide | N30: Claude/ChatGPT + Canva (AI) | O30: P05 | P30: 4.2.4, 5.2.4 | Q30: Phan Hữu Vinh (BE) | R30: Nguyễn Thị Thu Huyền (QA) | S30: Nguyễn Mậu Thái Duy (PM) | T30: =WORKDAY(D30,-2) -> 46356 | U30: =WORKDAY(D30,-1) -> 46357 | W30: =IF(V30="","",IF(V30<=U30,"Đúng hạn","Trễ")) | Y30: Chưa làm
A31: 27 | B31: LI07 | C31: =MATCH(D31,Tong_quan!$B$27:$B$39,1) -> 9 | D31: =DATE(2026,12,4) -> 46360 | E31: =CHOOSE(WEEKDAY(D31),"CN","Thứ 2","Thứ 3","Thứ 4","Thứ 5","Thứ 6","Thứ 7") -> Thứ 6 | F31: 08:00 | G31: LinkedIn | H31: Kiểm thử từ sớm: 58 test case trước khi code xong | I31: =INDEX(Tong_quan!$D$27:$D$39,C31) -> Phát triển / Kiểm thử | J31: Kỹ thuật & quy trình | K31: Bài viết + 1 test case mẫu | L31: Kế hoạch kiểm thử, bộ test case (6.1.1) | M31: Viết nháp bài từ góc nhìn tester | N31: Claude/ChatGPT | O31: P03 | P31: 6.1.1 | Q31: Nguyễn Thị Thu Huyền (QA) | R31: Nguyễn Anh Dũng (BA) | S31: Nguyễn Mậu Thái Duy (PM) | T31: =WORKDAY(D31,-2) -> 46358 | U31: =WORKDAY(D31,-1) -> 46359 | W31: =IF(V31="","",IF(V31<=U31,"Đúng hạn","Trễ")) | Y31: Chưa làm
A32: 28 | B32: FB12 | C32: =MATCH(D32,Tong_quan!$B$27:$B$39,1) -> 10 | D32: =DATE(2026,12,8) -> 46364 | E32: =CHOOSE(WEEKDAY(D32),"CN","Thứ 2","Thứ 3","Thứ 4","Thứ 5","Thứ 6","Thứ 7") -> Thứ 3 | F32: 20:00 | G32: Facebook | H32: Xuất báo cáo tháng trong 10 giây thay vì 1 ngày | I32: =INDEX(Tong_quan!$D$27:$D$39,C32) -> Kiểm thử | J32: Tính năng sản phẩm | K32: Ảnh/GIF + caption | L32: Chức năng xuất CSV/PDF (4.3.1); file PDF mẫu | M32: Viết caption; chọn ảnh minh hoạ | N32: Claude/ChatGPT + Canva (AI) | O32: P01 | P32: 4.3.1 | Q32: Phan Hữu Vinh (BE) | R32: Nguyễn Thị Thu Huyền (QA) | S32: Nguyễn Mậu Thái Duy (PM) | T32: =WORKDAY(D32,-2) -> 46360 | U32: =WORKDAY(D32,-1) -> 46363 | W32: =IF(V32="","",IF(V32<=U32,"Đúng hạn","Trễ")) | Y32: Chưa làm | AA32: “10 giây” phải đo lại trên bản build trước khi đăng
A33: 29 | B33: TT08 | C33: =MATCH(D33,Tong_quan!$B$27:$B$39,1) -> 10 | D33: =DATE(2026,12,9) -> 46365 | E33: =CHOOSE(WEEKDAY(D33),"CN","Thứ 2","Thứ 3","Thứ 4","Thứ 5","Thứ 6","Thứ 7") -> Thứ 4 | F33: 19:00 | G33: TikTok/Reels | H33: Thử “phá” phân quyền: nhân viên có xem được giá nhập không? | I33: =INDEX(Tong_quan!$D$27:$D$39,C33) -> Kiểm thử | J33: Kỹ thuật & quy trình | K33: Video quay màn hình 9:16, 30–45 giây | L33: Kết quả kiểm thử phân quyền (6.2.2) | M33: Viết kịch bản thử nghiệm; phụ đề | N33: Claude/ChatGPT + CapCut | O33: P02, P08 | P33: 6.2.2 | Q33: Nguyễn Thị Thu Huyền (QA) | R33: Nguyễn Anh Dũng (BA) | S33: Nguyễn Mậu Thái Duy (PM) | T33: =WORKDAY(D33,-2) -> 46363 | U33: =WORKDAY(D33,-1) -> 46364 | W33: =IF(V33="","",IF(V33<=U33,"Đúng hạn","Trễ")) | Y33: Chưa làm | AA33: Không quay token, file .env, URL quản trị
A34: 30 | B34: FB13 | C34: =MATCH(D34,Tong_quan!$B$27:$B$39,1) -> 10 | D34: =DATE(2026,12,11) -> 46367 | E34: =CHOOSE(WEEKDAY(D34),"CN","Thứ 2","Thứ 3","Thứ 4","Thứ 5","Thứ 6","Thứ 7") -> Thứ 6 | F34: 20:00 | G34: Facebook | H34: Dashboard nên hiển thị thêm chỉ số nào? (bình chọn) | I34: =INDEX(Tong_quan!$D$27:$D$39,C34) -> Kiểm thử | J34: Kiến thức nghiệp vụ | K34: Bình chọn (poll) + ảnh | L34: Danh sách KPI hiện có (FR01–FR02); đề xuất cho giai đoạn 2 | M34: Viết câu hỏi bình chọn và 4 lựa chọn | N34: Claude/ChatGPT | O34: P01 | P34: 2.2.1 | Q34: Nguyễn Anh Dũng (BA) | R34: Nguyễn Thị Thu Huyền (QA) | S34: Nguyễn Mậu Thái Duy (PM) | T34: =WORKDAY(D34,-2) -> 46365 | U34: =WORKDAY(D34,-1) -> 46366 | W34: =IF(V34="","",IF(V34<=U34,"Đúng hạn","Trễ")) | Y34: Chưa làm
A35: 31 | B35: LI08 | C35: =MATCH(D35,Tong_quan!$B$27:$B$39,1) -> 11 | D35: =DATE(2026,12,15) -> 46371 | E35: =CHOOSE(WEEKDAY(D35),"CN","Thứ 2","Thứ 3","Thứ 4","Thứ 5","Thứ 6","Thứ 7") -> Thứ 3 | F35: 08:00 | G35: LinkedIn | H35: Kiểm thử hiệu năng: trang Tổng quan mở dưới 2 giây với 2 năm dữ liệu | I35: =INDEX(Tong_quan!$D$27:$D$39,C35) -> Kiểm thử | J35: Kỹ thuật & quy trình | K35: Bài viết + ảnh kết quả đo | L35: Báo cáo kiểm thử hiệu năng (6.2.3) | M35: Viết nháp bài; gợi ý cách trình bày số đo | N35: Claude/ChatGPT | O35: P03 | P35: 6.2.3 | Q35: Nguyễn Thị Thu Huyền (QA) | R35: Nguyễn Anh Dũng (BA) | S35: Nguyễn Mậu Thái Duy (PM) | T35: =WORKDAY(D35,-2) -> 46367 | U35: =WORKDAY(D35,-1) -> 46370 | W35: =IF(V35="","",IF(V35<=U35,"Đúng hạn","Trễ")) | Y35: Chưa làm | AA35: Chỉ đăng số đo thật từ báo cáo
A36: 32 | B36: TT09 | C36: =MATCH(D36,Tong_quan!$B$27:$B$39,1) -> 11 | D36: =DATE(2026,12,16) -> 46372 | E36: =CHOOSE(WEEKDAY(D36),"CN","Thứ 2","Thứ 3","Thứ 4","Thứ 5","Thứ 6","Thứ 7") -> Thứ 4 | F36: 19:00 | G36: TikTok/Reels | H36: Tuần sửa lỗi: hậu trường trước buổi nghiệm thu | I36: =INDEX(Tong_quan!$D$27:$D$39,C36) -> Kiểm thử | J36: Hậu trường dự án | K36: Video dọc 9:16, 30 giây | L36: Clip làm việc; ảnh danh sách lỗi đã che thông tin (6.2.4) | M36: Viết kịch bản; phụ đề | N36: Claude/ChatGPT + CapCut | O36: P02, P08 | P36: 6.2.4 | Q36: Nguyễn Thị Thu Huyền (QA) | R36: Nguyễn Anh Dũng (BA) | S36: Nguyễn Mậu Thái Duy (PM) | T36: =WORKDAY(D36,-2) -> 46370 | U36: =WORKDAY(D36,-1) -> 46371 | W36: =IF(V36="","",IF(V36<=U36,"Đúng hạn","Trễ")) | Y36: Chưa làm
A37: 33 | B37: FB14 | C37: =MATCH(D37,Tong_quan!$B$27:$B$39,1) -> 11 | D37: =DATE(2026,12,18) -> 46374 | E37: =CHOOSE(WEEKDAY(D37),"CN","Thứ 2","Thứ 3","Thứ 4","Thứ 5","Thứ 6","Thứ 7") -> Thứ 6 | F37: 20:00 | G37: Facebook | H37: Thư mời buổi nghiệm thu và demo PharmaDash | I37: =INDEX(Tong_quan!$D$27:$D$39,C37) -> Kiểm thử | J37: Sự kiện & demo | K37: Poster + caption | L37: Giờ, địa điểm buổi nghiệm thu (PM xác nhận); ảnh sản phẩm | M37: Thiết kế poster; viết lời mời | N37: Claude/ChatGPT + Canva (AI) | O37: P06, P01 | P37: 6.3.1 | Q37: Nguyễn Mậu Thái Duy (PM) | R37: Nguyễn Anh Dũng (BA) | S37: Nguyễn Anh Dũng (BA) | T37: =WORKDAY(D37,-2) -> 46372 | U37: =WORKDAY(D37,-1) -> 46373 | W37: =IF(V37="","",IF(V37<=U37,"Đúng hạn","Trễ")) | Y37: Chưa làm
A38: 34 | B38: FB15 | C38: =MATCH(D38,Tong_quan!$B$27:$B$39,1) -> 12 | D38: =DATE(2026,12,22) -> 46378 | E38: =CHOOSE(WEEKDAY(D38),"CN","Thứ 2","Thứ 3","Thứ 4","Thứ 5","Thứ 6","Thứ 7") -> Thứ 3 | F38: 20:00 | G38: Facebook | H38: Hướng dẫn sử dụng nhanh theo vai trò | I38: =INDEX(Tong_quan!$D$27:$D$39,C38) -> Nghiệm thu | J38: Tính năng sản phẩm | K38: Carousel 6 slide | L38: Hướng dẫn sử dụng theo vai trò (7.2.1); ảnh màn hình | M38: Chuyển hướng dẫn thành 6 slide | N38: Claude/ChatGPT + Canva (AI) | O38: P05 | P38: 7.2.1 | Q38: Nguyễn Anh Dũng (BA) | R38: Nguyễn Thị Thu Huyền (QA) | S38: Nguyễn Mậu Thái Duy (PM) | T38: =WORKDAY(D38,-2) -> 46374 | U38: =WORKDAY(D38,-1) -> 46377 | W38: =IF(V38="","",IF(V38<=U38,"Đúng hạn","Trễ")) | Y38: Chưa làm
A39: 35 | B39: YT03 | C39: =MATCH(D39,Tong_quan!$B$27:$B$39,1) -> 12 | D39: =DATE(2026,12,23) -> 46379 | E39: =CHOOSE(WEEKDAY(D39),"CN","Thứ 2","Thứ 3","Thứ 4","Thứ 5","Thứ 6","Thứ 7") -> Thứ 4 | F39: 19:30 | G39: YouTube | H39: Demo đầy đủ PharmaDash (8–10 phút) | I39: =INDEX(Tong_quan!$D$27:$D$39,C39) -> Nghiệm thu | J39: Sự kiện & demo | K39: Video ngang 16:9, 8–10 phút | L39: Kịch bản demo; quay màn hình bản UAT (6.3.1) | M39: Viết kịch bản demo, tiêu đề, mô tả, chapters; phụ đề | N39: Claude/ChatGPT + CapCut | O39: P04, P07, P08 | P39: 6.3.1 | Q39: Võ Thị Minh Thơ (FE) | R39: Nguyễn Thị Thu Huyền (QA) | S39: Nguyễn Mậu Thái Duy (PM) | T39: =WORKDAY(D39,-2) -> 46377 | U39: =WORKDAY(D39,-1) -> 46378 | W39: =IF(V39="","",IF(V39<=U39,"Đúng hạn","Trễ")) | Y39: Chưa làm
A40: 36 | B40: FB16 | C40: =MATCH(D40,Tong_quan!$B$27:$B$39,1) -> 12 | D40: =DATE(2026,12,24) -> 46380 | E40: =CHOOSE(WEEKDAY(D40),"CN","Thứ 2","Thứ 3","Thứ 4","Thứ 5","Thứ 6","Thứ 7") -> Thứ 5 | F40: 20:00 | G40: Facebook | H40: Đào tạo người dùng tại 2 chi nhánh | I40: =INDEX(Tong_quan!$D$27:$D$39,C40) -> Nghiệm thu | J40: Hậu trường dự án | K40: Album ảnh + caption | L40: Ảnh buổi đào tạo (7.2.2); danh sách tham dự | M40: Viết caption từ biên bản đào tạo | N40: Claude/ChatGPT | O40: P01 | P40: 7.2.2 | Q40: Nguyễn Anh Dũng (BA) | R40: Nguyễn Thị Thu Huyền (QA) | S40: Nguyễn Mậu Thái Duy (PM) | T40: =WORKDAY(D40,-2) -> 46378 | U40: =WORKDAY(D40,-1) -> 46379 | W40: =IF(V40="","",IF(V40<=U40,"Đúng hạn","Trễ")) | Y40: Chưa làm | AA40: Xin phép người xuất hiện trong ảnh
A41: 37 | B41: FB17 | C41: =MATCH(D41,Tong_quan!$B$27:$B$39,1) -> 13 | D41: =DATE(2026,12,29) -> 46385 | E41: =CHOOSE(WEEKDAY(D41),"CN","Thứ 2","Thứ 3","Thứ 4","Thứ 5","Thứ 6","Thứ 7") -> Thứ 3 | F41: 20:00 | G41: Facebook | H41: PharmaDash chính thức go-live | I41: =INDEX(Tong_quan!$D$27:$D$39,C41) -> Triển khai | J41: Sự kiện & demo | K41: Ảnh bìa + caption | L41: Biên bản go-live (7.1.2); ảnh sản phẩm | M41: Viết caption; tạo ảnh bìa | N41: Claude/ChatGPT + Canva (AI) | O41: P01, P06 | P41: 7.1.2 | Q41: Nguyễn Mậu Thái Duy (PM) | R41: Nguyễn Anh Dũng (BA) | S41: Nguyễn Anh Dũng (BA) | T41: =WORKDAY(D41,-2) -> 46381 | U41: =WORKDAY(D41,-1) -> 46384 | W41: =IF(V41="","",IF(V41<=U41,"Đúng hạn","Trễ")) | Y41: Chưa làm
...

Sheet Quy_trinh_AI
A1: QUY TRÌNH: AI LÀM GÌ, LÀM THẾ NÀO, KHI NÀO
A2: D = ngày đăng trong Lich_dang. Mọi bài đi qua đủ 7 bước; AI chỉ tạo bản nháp, con người quyết định nội dung cuối.
A4: A. Các bước sản xuất một bài
A5: Bước | B5: Việc | C5: Ai làm | D5: Công cụ | E5: Đầu vào | F5: Đầu ra | G5: Thời điểm | H5: Xong khi
A6: 1 | B6: Viết brief | C6: Người chuẩn bị | D6: Mẫu brief (sheet Prompt_mau) | E6: Kết quả task WBS liên quan, ảnh/clip thật | F6: Brief 6 dòng | G6: D-2, buổi sáng | H6: Brief có dữ kiện đúng và danh sách tính năng ĐÃ có
A7: 2 | B7: AI viết nháp chữ: caption, kịch bản, bài LinkedIn | C7: AI (người chuẩn bị chạy) | D7: Claude/ChatGPT | E7: Brief + prompt mẫu P01–P05, P07, P09 | F7: 2–3 phương án nháp | G7: D-2 | H7: Chọn được 1 phương án để sửa
A8: 3 | B8: AI tạo hình/video thô: ảnh bìa, carousel, poster, phụ đề, giọng đọc | C8: AI (người chuẩn bị chạy) | D8: Canva (AI), CapCut | E8: Bản nháp chữ, ảnh chụp màn hình, clip quay màn hình (OBS) | F8: Ảnh/video thô | G8: D-2 | H8: Có file thô đúng tỷ lệ kênh (sheet Kenh)
A9: 4 | B9: AI tự soát + người sửa | C9: AI rồi người chuẩn bị | D9: Claude/ChatGPT (P10) | E9: Bản nháp chữ + hình | F9: Bản đã sửa | G9: D-2, cuối ngày | H9: Đã xử lý hết các câu P10 đánh dấu cần kiểm chứng
A10: 5 | B10: Kiểm tra nội dung theo checklist | C10: Người kiểm tra | D10: Sheet Kiem_duyet; mở sản phẩm thật để đối chiếu | E10: Bản đã sửa | F10: Bản đạt checklist | G10: D-1, buổi sáng | H10: Cột Qua checklist? = Đạt
A11: 6 | B11: Duyệt cuối | C11: Người duyệt | D11: — | E11: Bản đạt checklist | F11: Bản cuối | G11: D-1 (hạn duyệt) | H11: Trạng thái = Đã duyệt; ghi Ngày duyệt thực tế
A12: 7 | B12: “Đăng” mô phỏng và lưu minh chứng | C12: Người chuẩn bị | D12: Thư mục minh chứng của nhóm | E12: Bản cuối | F12: File cuối + ảnh xem trước (preview) theo giao diện kênh | G12: D, giờ đăng | H12: Trạng thái = Đã đăng (mô phỏng); có link ở cột Link. KHÔNG bấm đăng thật
A13: Hằng tuần (thứ 6, cùng buổi họp tiến độ tuần – WBS 1.3.1): PM dùng AI tóm tắt ghi chú các bài trong tuần thành 3 điểm làm tốt / 3 điểm cần sửa; đưa vào biên bản họp.
A15: B. Phân vai: AI làm gì – con người làm gì
B16: AI làm (bản nháp) | E16: Con người làm (AI không làm)
A17: 1 | B17: Viết caption, kịch bản video, bài LinkedIn, thư mời từ brief/biên bản | E17: Cung cấp dữ kiện thật, ảnh chụp và clip quay màn hình
A18: 2 | B18: Tóm tắt biên bản họp tuần, buổi demo, khảo sát, hướng dẫn sử dụng thành bài ngắn | E18: Quyết định thông điệp và chọn phương án
A19: 3 | B19: Đề xuất tiêu đề, hashtag, mô tả và chapters cho YouTube | E19: Kiểm tra tính năng nhắc tới đã có thật trong bản build
A20: 4 | B20: Dàn trang carousel, poster, infographic, ảnh bìa, mockup | E20: Che dữ liệu nhạy cảm, secret, URL quản trị trong ảnh/clip
A21: 5 | B21: Tạo phụ đề tự động và giọng đọc từ lời thoại đã duyệt | E21: Sửa phụ đề, nghe lại giọng đọc, chỉnh thuật ngữ
A22: 6 | B22: Tự soát bản nháp: đánh dấu câu cần kiểm chứng (P10) | E22: Duyệt cuối và chịu trách nhiệm nội dung
A24: C. Công cụ
B25: Công cụ | C25: Dùng để | E25: Kênh | F25: Ai dùng nhiều | G25: Lưu ý
A26: 1 | B26: Claude / ChatGPT | C26: Viết nháp, tóm tắt, kịch bản, tiêu đề/hashtag, tự soát (P10) | E26: Cả 4 kênh | F26: Cả nhóm | G26: Không dán mật khẩu, chuỗi kết nối, secret, dữ liệu thật vào prompt
A27: 2 | B27: Canva (tính năng AI) | C27: Ảnh bìa, carousel, poster, infographic, mockup, làm mờ ảnh | E27: Facebook, LinkedIn, YouTube (thumbnail) | F27: BA, BE, QA | G27: Không dùng logo/tên nhà thuốc, chuỗi dược hay phần mềm bán hàng có thật
A28: 3 | B28: CapCut | C28: Dựng video, phụ đề tự động, giọng đọc AI | E28: TikTok/Reels, YouTube | F28: FE, QA | G28: Chỉ dùng nhạc trong thư viện được phép của công cụ/nền tảng
A29: 4 | B29: OBS Studio (không phải AI) | C29: Quay màn hình demo | E29: TikTok/Reels, YouTube | F29: FE | G29: Đăng nhập bằng tài khoản demo, dữ liệu giả
A30: Chi phí: ưu tiên gói miễn phí hoặc tài khoản sẵn có; nhóm tự kiểm tra giới hạn gói hiện tại của từng công cụ. Cần trả phí → báo PM trước.

Sheet Prompt_mau
A1: MẪU BRIEF VÀ PROMPT MẪU
A2: Thay phần trong [ngoặc vuông] bằng nội dung thật. Luôn dán brief kèm prompt; chạy P10 trước khi gửi người kiểm tra.
A4: Mẫu brief (người chuẩn bị điền trước khi dùng AI)
A5: Mục | B5: Điền gì | C5: Ví dụ (bài FB07 “Mỗi người chỉ thấy đúng phần việc của mình: phân quyền”)
A6: Mục tiêu bài | B6: Người xem cần hiểu/làm gì sau khi xem | C6: Hiểu PharmaDash có đăng nhập an toàn và mỗi vai trò chỉ thấy đúng dữ liệu của mình
A7: Thông điệp (1 câu) | B7: Một câu duy nhất | C7: Nhân viên bán hàng không thấy giá nhập và lợi nhuận; quản lý chỉ thấy chi nhánh của mình
A8: Dữ kiện đúng | B8: Gạch đầu dòng, lấy từ task WBS | C8: - Đăng nhập bằng JWT - 3 vai trò: Chủ nhà thuốc, Quản lý, Nhân viên bán hàng - Mật khẩu được băm (bcrypt); quyền được kiểm tra ở máy chủ
A9: Tính năng ĐÃ có | B9: Chỉ liệt kê cái đã chạy được | C9: Đăng nhập, phân quyền 3 vai trò, chọn chi nhánh
A10: Ảnh/clip có sẵn | B10: Tên file hoặc link | C10: dangnhap.png, tongquan_chu.png, tongquan_nhanvien.png (dữ liệu giả)
A11: Cần tránh | B11: Điều không được nói/hiện | C11: Không hứa “bảo mật tuyệt đối”; không hiện JWT secret, file .env, URL quản trị
A13: Prompt mẫu
A14: Mã | B14: Dùng cho | C14: Công cụ | D14: Prompt mẫu | E14: Dán kèm | F14: Kiểm tra sau khi AI trả kết quả
A15: P01 | B15: Caption Facebook | C15: Claude/ChatGPT | D15: Bạn là người viết nội dung cho fanpage của dự án PharmaDash – Dashboard điều hành chuỗi nhà thuốc (đồ án sinh viên Nhóm Hữu Duyên). Dựa trên brief bên dưới, viết 3 phương án caption Facebook, mỗi phương án 80–150 từ, giọng thân thiện, câu đầu gây chú ý, cuối bài có 1 lời kêu gọi (bình luận hoặc xem video). Chỉ dùng thông tin trong brief, không thêm số liệu hay tính năng khác. Mỗi phương án kèm 3–5 hashtag. Brief: [dán brief] | E15: Brief; biên bản liên quan | F15: Có câu nào nói tính năng chưa làm? Có số liệu không có trong brief?
A16: P02 | B16: Kịch bản TikTok/Reels 20–45 giây | C16: Claude/ChatGPT | D16: Viết kịch bản video dọc [30] giây cho TikTok/Reels về: [chủ đề]. Khán giả: sinh viên và người đi làm không chuyên CNTT. Trình bày dạng bảng: Giây | Cảnh quay | Lời thoại | Chữ trên màn hình. 3 giây đầu là câu hỏi hoặc tình huống gây tò mò. Chỉ dùng cảnh quay nhóm có: [danh sách clip]. Chỉ nhắc các tính năng: [tính năng đã xong]. | E16: Brief; danh sách clip | F16: Cảnh nào không quay được? Thời lượng cộng lại có đúng không?
A17: P03 | B17: Bài LinkedIn | C17: Claude/ChatGPT | D17: Viết bài LinkedIn 150–250 từ bằng tiếng Việt, giọng chuyên nghiệp nhưng gần gũi, từ góc nhìn [vai trò: PM/BA/BE/FE/QA] trong dự án PharmaDash – Dashboard điều hành chuỗi nhà thuốc (đồ án sinh viên Nhóm Hữu Duyên). Cấu trúc: bối cảnh (1–2 câu) → vấn đề gặp phải → cách nhóm giải quyết → 2–3 bài học. Không phóng đại, không dùng số liệu ngoài ghi chú. Kết bằng 1 câu hỏi mở cho người đọc. Ghi chú: [dán] | E17: Ghi chú kỹ thuật/biên bản | F17: Bài học có đúng là của nhóm không? Thuật ngữ đúng chưa?
A18: P04 | B18: Kịch bản video YouTube (giới thiệu/demo) | C18: Claude/ChatGPT | D18: Viết kịch bản video demo [5–7] phút cho sản phẩm [tên]. Luồng demo theo đúng thứ tự: [bước 1 → bước n]. Mỗi đoạn ghi: thời lượng, thao tác trên màn hình, lời dẫn. Có mở đầu 20 giây (nêu vấn đề) và kết 20 giây (tóm tắt + kêu gọi). Sau đó đề xuất 3 tiêu đề (≤70 ký tự), mô tả 100 từ và danh sách mốc thời gian (chapters). | E18: Kịch bản demo; danh sách màn hình | F18: Luồng có khớp bản build? Tổng thời lượng có vừa không?
A19: P05 | B19: Carousel 4–8 slide | C19: Claude/ChatGPT → Canva (AI) | D19: Chuyển nội dung sau thành carousel [5] slide cho Facebook. Mỗi slide: tiêu đề ≤8 từ, nội dung ≤25 từ, gợi ý hình minh hoạ (ảnh chụp màn hình nào hoặc biểu tượng). Slide 1 là câu hỏi/tiêu đề gây chú ý; slide cuối là tóm tắt + lời kêu gọi. Nội dung: [dán] | E19: Nội dung gốc; ảnh chụp màn hình | F19: Chữ trên slide có bị tràn? Ảnh có lộ dữ liệu không?
A20: P06 | B20: Ảnh bìa / poster / infographic | C20: Canva (AI) | D20: Thiết kế [ảnh bìa/poster/infographic] tỷ lệ [1:1 | 4:5 | 16:9] cho dự án PharmaDash – Dashboard điều hành nhà thuốc. Phong cách tối giản, chuyên nghiệp, màu chủ đạo tím và trắng, biểu tượng hộp thuốc/lịch/biểu đồ. Tiêu đề: “[tiêu đề]”. Không dùng logo hay tên nhà thuốc, chuỗi dược có thật, không vẽ vỉ thuốc có nhãn hiệu thật, không dùng hình người có thật. | E20: Tiêu đề; ảnh sản phẩm (nếu có) | F20: Có logo/thương hiệu thật lọt vào? Chữ tiếng Việt có lỗi dấu?
A21: P07 | B21: Tiêu đề & hashtag | C21: Claude/ChatGPT | D21: Đề xuất 5 tiêu đề (≤60 ký tự) và 8 hashtag (tiếng Việt và tiếng Anh) cho [kênh] về nội dung: [tóm tắt]. Đánh dấu 2 tiêu đề rõ nghĩa nhất và giải thích ngắn vì sao. | E21: Tóm tắt bài | F21: Tiêu đề có gây hiểu nhầm hoặc giật tít quá không?
A22: P08 | B22: Phụ đề & giọng đọc | C22: CapCut | D22: Các bước trong CapCut: (1) tạo phụ đề tự động; (2) rà từng dòng, sửa thuật ngữ JWT, FEFO, Dashboard, KPI, UAT, tên thành viên; (3) nếu cần giọng đọc, dán lời thoại ĐÃ DUYỆT vào tính năng chuyển văn bản thành giọng nói; (4) nghe lại toàn bộ trước khi xuất. | E22: Lời thoại đã duyệt; clip | F22: Phụ đề có lệch thời gian/sai chính tả? Giọng đọc phát âm thuật ngữ đúng?
A23: P09 | B23: Recap / tổng kết | C23: Claude/ChatGPT | D23: Từ biên bản họp tiến độ tuần / buổi demo bên dưới, viết bài recap 120–180 từ gồm 3 phần: Đã hoàn thành, Bài học, Giai đoạn tiếp theo. Chỉ dùng thông tin trong biên bản. Không nêu lỗi hay khó khăn cá nhân của từng thành viên. Biên bản: [dán] | E23: Biên bản họp tuần / buổi demo | F23: Có nội dung nội bộ không nên công khai?
A24: P10 | B24: AI tự soát bản nháp (chạy cho mọi bài) | C24: Claude/ChatGPT | D24: Đọc bản nháp sau và liệt kê, KHÔNG viết lại bài: (1) mọi câu khẳng định về tính năng, số liệu, ngày tháng cần người kiểm chứng; (2) chỗ có thể khiến người đọc nghĩ đây là sản phẩm thương mại hoặc của nhà thuốc thật; (3) câu có thể bị hiểu là quảng cáo thuốc hoặc khuyên dùng thuốc; (4) lỗi chính tả, thuật ngữ. Bản nháp: [dán] | E24: Bản nháp | F24: Người chuẩn bị xử lý hết từng mục AI liệt kê

Sheet Kenh
A1: KẾ HOẠCH THEO KÊNH
A2: Khung giờ là lựa chọn của nhóm, chưa dựa trên số liệu tương tác. Cột Số bài tự đếm từ Lich_dang.
A4: Kênh | B4: Mục đích | C4: Đối tượng chính | D4: Định dạng chính | E4: Tần suất | F4: Khung giờ dự kiến | G4: Độ dài / tỷ lệ | H4: Giọng văn | I4: AI hỗ trợ chính | J4: Số bài
A5: Facebook | B5: Cập nhật tiến độ, giới thiệu tính năng, kiến thức nhà thuốc, sự kiện demo | C5: Bạn cùng lớp, giảng viên, chủ và nhân viên nhà thuốc (giả định) | D5: Ảnh, carousel, poster, infographic, album | E5: 1–2 bài/tuần (17 bài) | F5: 20:00 | G5: Caption 80–150 từ; ảnh 1:1 hoặc 4:5 | H5: Thân thiện, dễ hiểu | I5: Caption, carousel, poster, infographic | J5: =COUNTIF(Lich_dang!$G$5:$G$43,A5) -> 17
A6: TikTok/Reels | B6: Thu hút chú ý, hậu trường, demo ngắn | C6: Sinh viên, người trẻ | D6: Video dọc 9:16 | E6: Khoảng 1 bài/tuần (10 bài) | F6: 0.79166667 | G6: 20–45 giây | H6: Nhanh, vui, có hook 3 giây đầu | I6: Kịch bản, phụ đề, giọng đọc | J6: =COUNTIF(Lich_dang!$G$5:$G$43,A6) -> 10
A7: LinkedIn | B7: Chia sẻ chuyên môn, làm portfolio cá nhân | C7: Nhà tuyển dụng, người làm ngành | D7: Bài viết + ảnh/sơ đồ | E7: Khoảng 1 bài/tuần (9 bài) | F7: 0.33333333 | G7: 150–250 từ | H7: Chuyên nghiệp, có bài học cụ thể | I7: Nháp bài, sơ đồ | J7: =COUNTIF(Lich_dang!$G$5:$G$43,A7) -> 9
A8: YouTube | B8: Video giới thiệu và demo dài; lưu minh chứng | C8: Giảng viên, hội đồng, nhà tuyển dụng | D8: Video ngang 16:9 | E8: 3 video (tuần 4, 8, 12 – theo 3 buổi demo) | F8: 19:30 | G8: 3–10 phút | H8: Rõ ràng, theo luồng thao tác | I8: Kịch bản, phụ đề, tiêu đề/mô tả/chapters | J8: =COUNTIF(Lich_dang!$G$5:$G$43,A8) -> 3
A9: Tổng | J9: =SUM(J5:J8) -> 39

Sheet Kiem_duyet
A1: CHECKLIST KIỂM DUYỆT NỘI DUNG CÓ AI
A2: Người kiểm tra chạy checklist trước hạn duyệt (D-1). Mọi mục “Bắt buộc” phải đạt thì mới chọn Đạt ở cột Qua checklist? trong Lich_dang.
A4: STT | B4: Hạng mục kiểm tra | C4: Cách kiểm | D4: Ai kiểm | E4: Mức
A5: 1 | B5: Chỉ nhắc tính năng đã có trong bản build hiện tại | C5: Mở sản phẩm hoặc hỏi người phụ trách task WBS | D5: Người kiểm tra | E5: Bắt buộc
A6: 2 | B6: Không có số liệu, trích dẫn, thống kê do AI tự thêm; số liệu nào cũng có nguồn | C6: Chạy P10, đối chiếu từng câu với brief | D6: Người kiểm tra | E6: Bắt buộc
A7: 3 | B7: Ảnh/video chỉ dùng dữ liệu giả: không tên, SĐT khách hàng, đơn thuốc, giá nhập thật | C7: Xem từng khung hình, phóng to bảng dữ liệu | D7: Người kiểm tra | E7: Bắt buộc
A8: 4 | B8: Không lộ mật khẩu, chuỗi kết nối, JWT secret, file .env, URL quản trị | C8: Soi thanh địa chỉ, terminal, tab trình duyệt trong ảnh/clip | D8: Người kiểm tra | E8: Bắt buộc
A9: 5 | B9: Không dùng logo, tên, giao diện của nhà thuốc, chuỗi dược hay phần mềm bán hàng có thật | C9: Xem ảnh bìa, poster, mockup | D9: Người kiểm tra | E9: Bắt buộc
A10: 6 | B10: Ghi rõ đây là đồ án sinh viên, không phải sản phẩm thương mại | C10: Đọc caption/mô tả | D10: Người kiểm tra | E10: Bắt buộc
A11: 7 | B11: Ghi “Nội dung có sự hỗ trợ của AI” ở cuối bài/mô tả; nếu đăng thật thì bật nhãn nội dung AI khi nền tảng yêu cầu | C11: Đọc caption/mô tả | D11: Người kiểm tra | E11: Bắt buộc
A12: 8 | B12: Hình ảnh, nhạc, phông chữ được phép dùng (thư viện của công cụ/nền tảng) | C12: Kiểm tra nguồn từng thành phần | D12: Người kiểm tra | E12: Bắt buộc
A13: 9 | B13: Có sự đồng ý của thành viên xuất hiện trong ảnh/video | C13: Hỏi trực tiếp trong nhóm | D13: Người chuẩn bị | E13: Bắt buộc
A14: 10 | B14: Chính tả, dấu tiếng Việt, thuật ngữ (JWT, FEFO, Dashboard, KPI, UAT) thống nhất | C14: Đọc to một lượt; xem phụ đề | D14: Người kiểm tra | E14: Nên có
A15: 11 | B15: Đúng định dạng kênh: tỷ lệ, độ dài, thời lượng (sheet Kenh) | C15: So với sheet Kenh | D15: Người kiểm tra | E15: Nên có
A16: 12 | B16: Lưu file cuối + ảnh xem trước vào thư mục minh chứng, ghi link vào Lich_dang | C16: Mở link thử | D16: Người chuẩn bị | E16: Bắt buộc
A17: 13 | B17: Không quảng cáo thuốc, không khuyên dùng thuốc cụ thể; tên thuốc chỉ xuất hiện như dữ liệu mẫu trong ảnh màn hình | C17: Đọc caption, xem ảnh; đặc biệt cẩn thận với thuốc kê đơn | D17: Người kiểm tra | E17: Bắt buộc

Sheet Tong_hop
A1: TỔNG HỢP & KPI SẢN XUẤT NỘI DUNG
A2: Tất cả số liệu tự tính từ Lich_dang. Mục tiêu (chữ xanh dương) là số nhập tay, nhóm có thể sửa.
A4: A. KPI
A5: Chỉ số | C5: Thực tế | D5: Mục tiêu | E5: Cách tính
A6: Tổng số bài trong kế hoạch | C6: =COUNTA(Lich_dang!$B$5:$B$43) -> 39 | D6: 39 | E6: Đếm Mã bài trong Lich_dang
A7: Số bài đã duyệt hoặc “đăng” mô phỏng | C7: =COUNTIF(Lich_dang!$Y$5:$Y$43,"Đã duyệt")+COUNTIF(Lich_dang!$Y$5:$Y$43,"Đã đăng (mô phỏng)") -> 0 | D7: 39 | E7: Trạng thái = Đã duyệt hoặc Đã đăng (mô phỏng)
A8: Tỷ lệ hoàn thành | C8: =IF(C6=0,0,C7/C6) -> 0 | D8: 1 | E8: Bài đã duyệt / tổng bài
A9: Tỷ lệ duyệt đúng hạn | C9: =IF(COUNT(Lich_dang!$V$5:$V$43)=0,"Chưa có dữ liệu",COUNTIF(Lich_dang!$W$5:$W$43,"Đúng hạn")/COUNT(Lich_dang!$V$5:$V$43)) -> Chưa có dữ liệu | D9: 0.9 | E9: Bài duyệt trước/đúng hạn duyệt (D-1) / bài đã có ngày duyệt
A10: Tỷ lệ bài qua checklist | C10: =IF(C6=0,0,COUNTIF(Lich_dang!$X$5:$X$43,"Đạt")/C6) -> 0 | D10: 1 | E10: Qua checklist? = Đạt / tổng bài
A11: Số bài quá hạn duyệt chưa xử lý | C11: =SUMPRODUCT((Lich_dang!$U$5:$U$43<TODAY())*(Lich_dang!$Y$5:$Y$43<>"Đã duyệt")*(Lich_dang!$Y$5:$Y$43<>"Đã đăng (mô phỏng)")*(Lich_dang!$Y$5:$Y$43<>"Hoãn/đổi lịch")) -> 3 | D11: 0 | E11: Hạn duyệt đã qua (so với hôm nay) mà chưa duyệt, chưa hoãn
A13: B. Số bài theo tuần × kênh
A14: Tuần | B14: Giai đoạn | C14: Facebook | D14: TikTok/Reels | E14: LinkedIn | F14: YouTube | G14: Tổng
A15: 1 | B15: =INDEX(Tong_quan!$D$27:$D$39,A15) -> Khởi động | C15: =COUNTIFS(Lich_dang!$C$5:$C$43,$A15,Lich_dang!$G$5:$G$43,C$14) -> 1 | D15: =COUNTIFS(Lich_dang!$C$5:$C$43,$A15,Lich_dang!$G$5:$G$43,D$14) -> 1 | E15: =COUNTIFS(Lich_dang!$C$5:$C$43,$A15,Lich_dang!$G$5:$G$43,E$14) -> 1 | F15: =COUNTIFS(Lich_dang!$C$5:$C$43,$A15,Lich_dang!$G$5:$G$43,F$14) -> 0 | G15: =SUM(C15:F15) -> 3
A16: 2 | B16: =INDEX(Tong_quan!$D$27:$D$39,A16) -> Phân tích | C16: =COUNTIFS(Lich_dang!$C$5:$C$43,$A16,Lich_dang!$G$5:$G$43,C$14) -> 1 | D16: =COUNTIFS(Lich_dang!$C$5:$C$43,$A16,Lich_dang!$G$5:$G$43,D$14) -> 1 | E16: =COUNTIFS(Lich_dang!$C$5:$C$43,$A16,Lich_dang!$G$5:$G$43,E$14) -> 1 | F16: =COUNTIFS(Lich_dang!$C$5:$C$43,$A16,Lich_dang!$G$5:$G$43,F$14) -> 0 | G16: =SUM(C16:F16) -> 3
A17: 3 | B17: =INDEX(Tong_quan!$D$27:$D$39,A17) -> Phân tích | C17: =COUNTIFS(Lich_dang!$C$5:$C$43,$A17,Lich_dang!$G$5:$G$43,C$14) -> 1 | D17: =COUNTIFS(Lich_dang!$C$5:$C$43,$A17,Lich_dang!$G$5:$G$43,D$14) -> 1 | E17: =COUNTIFS(Lich_dang!$C$5:$C$43,$A17,Lich_dang!$G$5:$G$43,E$14) -> 1 | F17: =COUNTIFS(Lich_dang!$C$5:$C$43,$A17,Lich_dang!$G$5:$G$43,F$14) -> 0 | G17: =SUM(C17:F17) -> 3
A18: 4 | B18: =INDEX(Tong_quan!$D$27:$D$39,A18) -> Phân tích / Thiết kế | C18: =COUNTIFS(Lich_dang!$C$5:$C$43,$A18,Lich_dang!$G$5:$G$43,C$14) -> 2 | D18: =COUNTIFS(Lich_dang!$C$5:$C$43,$A18,Lich_dang!$G$5:$G$43,D$14) -> 0 | E18: =COUNTIFS(Lich_dang!$C$5:$C$43,$A18,Lich_dang!$G$5:$G$43,E$14) -> 0 | F18: =COUNTIFS(Lich_dang!$C$5:$C$43,$A18,Lich_dang!$G$5:$G$43,F$14) -> 1 | G18: =SUM(C18:F18) -> 3
A19: 5 | B19: =INDEX(Tong_quan!$D$27:$D$39,A19) -> Thiết kế | C19: =COUNTIFS(Lich_dang!$C$5:$C$43,$A19,Lich_dang!$G$5:$G$43,C$14) -> 1 | D19: =COUNTIFS(Lich_dang!$C$5:$C$43,$A19,Lich_dang!$G$5:$G$43,D$14) -> 1 | E19: =COUNTIFS(Lich_dang!$C$5:$C$43,$A19,Lich_dang!$G$5:$G$43,E$14) -> 1 | F19: =COUNTIFS(Lich_dang!$C$5:$C$43,$A19,Lich_dang!$G$5:$G$43,F$14) -> 0 | G19: =SUM(C19:F19) -> 3
A20: 6 | B20: =INDEX(Tong_quan!$D$27:$D$39,A20) -> Phát triển | C20: =COUNTIFS(Lich_dang!$C$5:$C$43,$A20,Lich_dang!$G$5:$G$43,C$14) -> 1 | D20: =COUNTIFS(Lich_dang!$C$5:$C$43,$A20,Lich_dang!$G$5:$G$43,D$14) -> 1 | E20: =COUNTIFS(Lich_dang!$C$5:$C$43,$A20,Lich_dang!$G$5:$G$43,E$14) -> 1 | F20: =COUNTIFS(Lich_dang!$C$5:$C$43,$A20,Lich_dang!$G$5:$G$43,F$14) -> 0 | G20: =SUM(C20:F20) -> 3
A21: 7 | B21: =INDEX(Tong_quan!$D$27:$D$39,A21) -> Phát triển | C21: =COUNTIFS(Lich_dang!$C$5:$C$43,$A21,Lich_dang!$G$5:$G$43,C$14) -> 2 | D21: =COUNTIFS(Lich_dang!$C$5:$C$43,$A21,Lich_dang!$G$5:$G$43,D$14) -> 1 | E21: =COUNTIFS(Lich_dang!$C$5:$C$43,$A21,Lich_dang!$G$5:$G$43,E$14) -> 0 | F21: =COUNTIFS(Lich_dang!$C$5:$C$43,$A21,Lich_dang!$G$5:$G$43,F$14) -> 0 | G21: =SUM(C21:F21) -> 3
A22: 8 | B22: =INDEX(Tong_quan!$D$27:$D$39,A22) -> Phát triển | C22: =COUNTIFS(Lich_dang!$C$5:$C$43,$A22,Lich_dang!$G$5:$G$43,C$14) -> 1 | D22: =COUNTIFS(Lich_dang!$C$5:$C$43,$A22,Lich_dang!$G$5:$G$43,D$14) -> 0 | E22: =COUNTIFS(Lich_dang!$C$5:$C$43,$A22,Lich_dang!$G$5:$G$43,E$14) -> 1 | F22: =COUNTIFS(Lich_dang!$C$5:$C$43,$A22,Lich_dang!$G$5:$G$43,F$14) -> 1 | G22: =SUM(C22:F22) -> 3
A23: 9 | B23: =INDEX(Tong_quan!$D$27:$D$39,A23) -> Phát triển / Kiểm thử | C23: =COUNTIFS(Lich_dang!$C$5:$C$43,$A23,Lich_dang!$G$5:$G$43,C$14) -> 1 | D23: =COUNTIFS(Lich_dang!$C$5:$C$43,$A23,Lich_dang!$G$5:$G$43,D$14) -> 1 | E23: =COUNTIFS(Lich_dang!$C$5:$C$43,$A23,Lich_dang!$G$5:$G$43,E$14) -> 1 | F23: =COUNTIFS(Lich_dang!$C$5:$C$43,$A23,Lich_dang!$G$5:$G$43,F$14) -> 0 | G23: =SUM(C23:F23) -> 3
A24: 10 | B24: =INDEX(Tong_quan!$D$27:$D$39,A24) -> Kiểm thử | C24: =COUNTIFS(Lich_dang!$C$5:$C$43,$A24,Lich_dang!$G$5:$G$43,C$14) -> 2 | D24: =COUNTIFS(Lich_dang!$C$5:$C$43,$A24,Lich_dang!$G$5:$G$43,D$14) -> 1 | E24: =COUNTIFS(Lich_dang!$C$5:$C$43,$A24,Lich_dang!$G$5:$G$43,E$14) -> 0 | F24: =COUNTIFS(Lich_dang!$C$5:$C$43,$A24,Lich_dang!$G$5:$G$43,F$14) -> 0 | G24: =SUM(C24:F24) -> 3
A25: 11 | B25: =INDEX(Tong_quan!$D$27:$D$39,A25) -> Kiểm thử | C25: =COUNTIFS(Lich_dang!$C$5:$C$43,$A25,Lich_dang!$G$5:$G$43,C$14) -> 1 | D25: =COUNTIFS(Lich_dang!$C$5:$C$43,$A25,Lich_dang!$G$5:$G$43,D$14) -> 1 | E25: =COUNTIFS(Lich_dang!$C$5:$C$43,$A25,Lich_dang!$G$5:$G$43,E$14) -> 1 | F25: =COUNTIFS(Lich_dang!$C$5:$C$43,$A25,Lich_dang!$G$5:$G$43,F$14) -> 0 | G25: =SUM(C25:F25) -> 3
A26: 12 | B26: =INDEX(Tong_quan!$D$27:$D$39,A26) -> Nghiệm thu | C26: =COUNTIFS(Lich_dang!$C$5:$C$43,$A26,Lich_dang!$G$5:$G$43,C$14) -> 2 | D26: =COUNTIFS(Lich_dang!$C$5:$C$43,$A26,Lich_dang!$G$5:$G$43,D$14) -> 0 | E26: =COUNTIFS(Lich_dang!$C$5:$C$43,$A26,Lich_dang!$G$5:$G$43,E$14) -> 0 | F26: =COUNTIFS(Lich_dang!$C$5:$C$43,$A26,Lich_dang!$G$5:$G$43,F$14) -> 1 | G26: =SUM(C26:F26) -> 3
A27: 13 | B27: =INDEX(Tong_quan!$D$27:$D$39,A27) -> Triển khai | C27: =COUNTIFS(Lich_dang!$C$5:$C$43,$A27,Lich_dang!$G$5:$G$43,C$14) -> 1 | D27: =COUNTIFS(Lich_dang!$C$5:$C$43,$A27,Lich_dang!$G$5:$G$43,D$14) -> 1 | E27: =COUNTIFS(Lich_dang!$C$5:$C$43,$A27,Lich_dang!$G$5:$G$43,E$14) -> 1 | F27: =COUNTIFS(Lich_dang!$C$5:$C$43,$A27,Lich_dang!$G$5:$G$43,F$14) -> 0 | G27: =SUM(C27:F27) -> 3
A28: Tổng | C28: =SUM(C15:C27) -> 17 | D28: =SUM(D15:D27) -> 10 | E28: =SUM(E15:E27) -> 9 | F28: =SUM(F15:F27) -> 3 | G28: =SUM(G15:G27) -> 39
A30: C. Số bài theo người chuẩn bị
A31: Thành viên | C31: Số bài chuẩn bị | D31: Số bài kiểm tra | E31: Số bài duyệt
A32: Nguyễn Mậu Thái Duy (PM) | C32: =COUNTIF(Lich_dang!$Q$5:$Q$43,$A32) -> 7 | D32: =COUNTIF(Lich_dang!$R$5:$R$43,$A32) -> 0 | E32: =COUNTIF(Lich_dang!$S$5:$S$43,$A32) -> 32
A33: Nguyễn Anh Dũng (BA) | C33: =COUNTIF(Lich_dang!$Q$5:$Q$43,$A33) -> 9 | D33: =COUNTIF(Lich_dang!$R$5:$R$43,$A33) -> 14 | E33: =COUNTIF(Lich_dang!$S$5:$S$43,$A33) -> 7
A34: Phan Hữu Vinh (BE) | C34: =COUNTIF(Lich_dang!$Q$5:$Q$43,$A34) -> 7 | D34: =COUNTIF(Lich_dang!$R$5:$R$43,$A34) -> 0 | E34: =COUNTIF(Lich_dang!$S$5:$S$43,$A34) -> 0
A35: Võ Thị Minh Thơ (FE) | C35: =COUNTIF(Lich_dang!$Q$5:$Q$43,$A35) -> 9 | D35: =COUNTIF(Lich_dang!$R$5:$R$43,$A35) -> 0 | E35: =COUNTIF(Lich_dang!$S$5:$S$43,$A35) -> 0
A36: Nguyễn Thị Thu Huyền (QA) | C36: =COUNTIF(Lich_dang!$Q$5:$Q$43,$A36) -> 7 | D36: =COUNTIF(Lich_dang!$R$5:$R$43,$A36) -> 25 | E36: =COUNTIF(Lich_dang!$S$5:$S$43,$A36) -> 0
A38: D. Số bài theo trạng thái
A39: Trạng thái | C39: Số bài
A40: Chưa làm | C40: =COUNTIF(Lich_dang!$Y$5:$Y$43,$A40) -> 39
A41: Đang soạn (AI nháp) | C41: =COUNTIF(Lich_dang!$Y$5:$Y$43,$A41) -> 0
A42: Chờ duyệt | C42: =COUNTIF(Lich_dang!$Y$5:$Y$43,$A42) -> 0
A43: Đã duyệt | C43: =COUNTIF(Lich_dang!$Y$5:$Y$43,$A43) -> 0
A44: Đã đăng (mô phỏng) | C44: =COUNTIF(Lich_dang!$Y$5:$Y$43,$A44) -> 0
...
