Workbook

Sheet HuongDan
B2: LỊCH DỰ ÁN PHARMADASH – Bài Lab QLDA CNTT
B3: Dự án giả định: xây dựng Dashboard điều hành cho chuỗi Nhà thuốc Hữu Duyên (hư cấu). Đơn vị thời gian: ngày làm việc (T2–T6).
B5: Quy ước màu
B6: Chữ xanh dương | C6: Số liệu đầu vào (giả định) – được phép sửa: giờ công, đơn giá, O/M/P, xác suất/tác động...
B7: Chữ đen | C7: Công thức – KHÔNG sửa, tự tính lại khi đầu vào thay đổi.
B8: Nền vàng | C8: Ô nhóm phải TỰ ĐIỀN (kết quả AI trong Claude Project để so sánh, rủi ro nhóm tự bổ sung...).
B10: Các sheet
B11: WBS | C11: WBS 3 cấp, giờ công từng gói công việc, tự kiểm tra quy tắc 8/80 và tổng giờ (quy tắc 100%).
B12: ChiPhi | C12: Ước lượng chi phí từ giờ công WBS × đơn giá theo vai trò + chi phí khác + dự phòng, so với ngân sách.
B13: PERT | C13: Ước lượng 3 điểm TE = (O + 4M + P)/6, ES/EF/LS/LF, Slack, đường găng, độ lệch chuẩn, xác suất kịp hạn. Cột "TE theo AI" để nhóm nhập kết quả Claude trả lời và so sánh.
B14: Gantt | C14: Biểu đồ Gantt tự vẽ từ ES/EF (đỏ = hoạt động găng, xanh = không găng, cột cam = hạn chót).
B15: NenLich | C15: Kịch bản nén lịch (fast-tracking + giảm phạm vi) – lịch mới, đường găng mới, xác suất kịp hạn.
B16: RuiRo | C16: Sổ đăng ký rủi ro (Risk Register), sắp theo điểm giảm dần. 2 dòng cuối để nhóm tự bổ sung.
B17: MaTran | C17: Ma trận xác suất × tác động 5×5, tự điền mã rủi ro theo sheet RuiRo.
B19: Lưu ý | C19: Các số O/M/P, giờ công, đơn giá là GIẢ ĐỊNH do AI đề xuất làm bản nháp – nhóm cần xem lại và điều chỉnh theo ý kiến của nhóm.
C20: Nếu sửa XS/TĐ trong sheet RuiRo, hãy sắp xếp lại bảng theo cột Điểm (Data → Sort) để đúng yêu cầu "sắp theo điểm giảm dần".
C21: Nếu thêm/bớt hoạt động PERT, phải sửa lại công thức ES (MAX EF của hoạt động trước) và LF (MIN LS của hoạt động sau).

Sheet WBS
A1: CẤU TRÚC PHÂN RÃ CÔNG VIỆC (WBS) – PHARMADASH
A2: Giờ công là giả định (chữ xanh). Cấp 1–2 tự cộng từ các gói công việc cấp 3. Quy tắc 8/80: mỗi gói 8–80 giờ công.
A4: Mã WBS | B4: Cấp | C4: Tên hạng mục / gói công việc | D4: Sản phẩm bàn giao | E4: Vai trò chính | F4: Giờ công | G4: Kiểm tra 8/80
A5: 1.0 | B5: 1 | C5: Quản lý dự án | D5: Hồ sơ quản lý dự án | E5: PM | F5: =SUMIFS($F$5:$F$78,$A$5:$A$78,"1.*",$B$5:$B$78,3) -> 156
A6: 1.1 | B6: 2 | C6: Khởi động dự án | D6: Charter đã phê duyệt | E6: PM | F6: =SUMIFS($F$5:$F$78,$A$5:$A$78,"1.1.*",$B$5:$B$78,3) -> 24
A7: 1.1.1 | B7: 3 | C7: Soạn và phê duyệt Project Charter | D7: Project Charter có chữ ký Sponsor | E7: PM | F7: 16 | G7: =IF(AND(F7>=8,F7<=80),"Đạt","Vi phạm 8/80") -> Đạt
A8: 1.1.2 | B8: 3 | C8: Họp khởi động (kick-off) | D8: Biên bản họp khởi động | E8: PM | F8: 8 | G8: =IF(AND(F8>=8,F8<=80),"Đạt","Vi phạm 8/80") -> Đạt
A9: 1.2 | B9: 2 | C9: Lập kế hoạch | D9: Kế hoạch quản lý dự án | E9: PM | F9: =SUMIFS($F$5:$F$78,$A$5:$A$78,"1.2.*",$B$5:$B$78,3) -> 44
A10: 1.2.1 | B10: 3 | C10: WBS và từ điển WBS | D10: WBS 3 cấp + từ điển WBS | E10: PM | F10: 16 | G10: =IF(AND(F10>=8,F10<=80),"Đạt","Vi phạm 8/80") -> Đạt
A11: 1.2.2 | B11: 3 | C11: Lịch dự án và dự toán chi phí | D11: File lịch PERT/Gantt, dự toán | E11: PM | F11: 16 | G11: =IF(AND(F11>=8,F11<=80),"Đạt","Vi phạm 8/80") -> Đạt
A12: 1.2.3 | B12: 3 | C12: Kế hoạch quản lý rủi ro | D12: Risk Register | E12: PM | F12: 12 | G12: =IF(AND(F12>=8,F12<=80),"Đạt","Vi phạm 8/80") -> Đạt
A13: 1.3 | B13: 2 | C13: Giám sát và kiểm soát | D13: Báo cáo tiến độ | E13: PM | F13: =SUMIFS($F$5:$F$78,$A$5:$A$78,"1.3.*",$B$5:$B$78,3) -> 76
A14: 1.3.1 | B14: 3 | C14: Họp tiến độ hằng tuần và báo cáo (13 tuần) | D14: 13 báo cáo tuần | E14: PM | F14: 52 | G14: =IF(AND(F14>=8,F14<=80),"Đạt","Vi phạm 8/80") -> Đạt
A15: 1.3.2 | B15: 3 | C15: Demo cuối tháng với Giám đốc (3 lần) | D15: 3 biên bản demo, danh sách yêu cầu thay đổi | E15: PM | F15: 24 | G15: =IF(AND(F15>=8,F15<=80),"Đạt","Vi phạm 8/80") -> Đạt
A16: 1.4 | B16: 2 | C16: Kết thúc dự án | D16: Hồ sơ đóng dự án | E16: PM | F16: =SUMIFS($F$5:$F$78,$A$5:$A$78,"1.4.*",$B$5:$B$78,3) -> 12
A17: 1.4.1 | B17: 3 | C17: Nghiệm thu, bàn giao và rút kinh nghiệm | D17: Biên bản nghiệm thu, báo cáo bài học | E17: PM | F17: 12 | G17: =IF(AND(F17>=8,F17<=80),"Đạt","Vi phạm 8/80") -> Đạt
A18: 2.0 | B18: 1 | C18: Phân tích yêu cầu | D18: Tài liệu SRS đã duyệt | E18: BA | F18: =SUMIFS($F$5:$F$78,$A$5:$A$78,"2.*",$B$5:$B$78,3) -> 104
A19: 2.1 | B19: 2 | C19: Khảo sát nghiệp vụ | D19: Báo cáo khảo sát | E19: BA | F19: =SUMIFS($F$5:$F$78,$A$5:$A$78,"2.1.*",$B$5:$B$78,3) -> 40
A20: 2.1.1 | B20: 3 | C20: Phỏng vấn chủ, quản lý, nhân viên 2 chi nhánh | D20: Biên bản phỏng vấn, quy trình hiện tại (AS-IS) | E20: BA | F20: 24 | G20: =IF(AND(F20>=8,F20<=80),"Đạt","Vi phạm 8/80") -> Đạt
A21: 2.1.2 | B21: 3 | C21: Khảo sát phần mềm bán hàng và file Excel tồn kho | D21: Báo cáo hiện trạng dữ liệu | E21: BA | F21: 16 | G21: =IF(AND(F21>=8,F21<=80),"Đạt","Vi phạm 8/80") -> Đạt
A22: 2.2 | B22: 2 | C22: Đặc tả yêu cầu | D22: SRS | E22: BA | F22: =SUMIFS($F$5:$F$78,$A$5:$A$78,"2.2.*",$B$5:$B$78,3) -> 64
A23: 2.2.1 | B23: 3 | C23: Viết user story và tiêu chí chấp nhận | D23: Product backlog có tiêu chí chấp nhận | E23: BA | F23: 32 | G23: =IF(AND(F23>=8,F23<=80),"Đạt","Vi phạm 8/80") -> Đạt
A24: 2.2.2 | B24: 3 | C24: Đặc tả use case và quy tắc nghiệp vụ (hạn dùng, phân quyền) | D24: Tài liệu use case | E24: BA | F24: 24 | G24: =IF(AND(F24>=8,F24<=80),"Đạt","Vi phạm 8/80") -> Đạt
A25: 2.2.3 | B25: 3 | C25: Rà soát và phê duyệt SRS với khách hàng | D25: SRS có xác nhận của khách hàng | E25: BA | F25: 8 | G25: =IF(AND(F25>=8,F25<=80),"Đạt","Vi phạm 8/80") -> Đạt
A26: 3.0 | B26: 1 | C26: Thiết kế hệ thống | D26: Tài liệu thiết kế | E26: BE | F26: =SUMIFS($F$5:$F$78,$A$5:$A$78,"3.*",$B$5:$B$78,3) -> 128
A27: 3.1 | B27: 2 | C27: Thiết kế kiến trúc và dữ liệu | D27: Tài liệu kiến trúc | E27: BE | F27: =SUMIFS($F$5:$F$78,$A$5:$A$78,"3.1.*",$B$5:$B$78,3) -> 56
A28: 3.1.1 | B28: 3 | C28: Thiết kế kiến trúc hệ thống | D28: Sơ đồ kiến trúc | E28: BE | F28: 16 | G28: =IF(AND(F28>=8,F28<=80),"Đạt","Vi phạm 8/80") -> Đạt
A29: 3.1.2 | B29: 3 | C29: Thiết kế CSDL (ERD, tồn kho theo lô) | D29: ERD, script tạo CSDL | E29: BE | F29: 24 | G29: =IF(AND(F29>=8,F29<=80),"Đạt","Vi phạm 8/80") -> Đạt
A30: 3.1.3 | B30: 3 | C30: Đặc tả API | D30: Danh sách API | E30: BE | F30: 16 | G30: =IF(AND(F30>=8,F30<=80),"Đạt","Vi phạm 8/80") -> Đạt
A31: 3.2 | B31: 2 | C31: Thiết kế giao diện | D31: Bộ thiết kế UI | E31: FE | F31: =SUMIFS($F$5:$F$78,$A$5:$A$78,"3.2.*",$B$5:$B$78,3) -> 72
A32: 3.2.1 | B32: 3 | C32: Design token và wireframe | D32: Wireframe, bảng màu, font | E32: FE | F32: 32 | G32: =IF(AND(F32>=8,F32<=80),"Đạt","Vi phạm 8/80") -> Đạt
A33: 3.2.2 | B33: 3 | C33: Mockup các màn hình chính | D33: Mockup 8 màn hình | E33: FE | F33: 40 | G33: =IF(AND(F33>=8,F33<=80),"Đạt","Vi phạm 8/80") -> Đạt
A34: 4.0 | B34: 1 | C34: Phát triển Backend | D34: API và CSDL hoạt động | E34: BE | F34: =SUMIFS($F$5:$F$78,$A$5:$A$78,"4.*",$B$5:$B$78,3) -> 340
A35: 4.1 | B35: 2 | C35: Nền tảng backend | D35: Khung dự án chạy được | E35: BE | F35: =SUMIFS($F$5:$F$78,$A$5:$A$78,"4.1.*",$B$5:$B$78,3) -> 40
A36: 4.1.1 | B36: 3 | C36: Khung dự án, CSDL, môi trường | D36: Mã nguồn khởi tạo, CSDL | E36: BE | F36: 16 | G36: =IF(AND(F36>=8,F36<=80),"Đạt","Vi phạm 8/80") -> Đạt
A37: 4.1.2 | B37: 3 | C37: Xác thực và phân quyền 3 vai trò | D37: API đăng nhập, phân quyền | E37: BE | F37: 24 | G37: =IF(AND(F37>=8,F37<=80),"Đạt","Vi phạm 8/80") -> Đạt
A38: 4.2 | B38: 2 | C38: API nghiệp vụ | D38: Bộ API nghiệp vụ | E38: BE | F38: =SUMIFS($F$5:$F$78,$A$5:$A$78,"4.2.*",$B$5:$B$78,3) -> 168
A39: 4.2.1 | B39: 3 | C39: API tổng quan (KPI, biểu đồ, top thuốc) | D39: API dashboard | E39: BE | F39: 40 | G39: =IF(AND(F39>=8,F39<=80),"Đạt","Vi phạm 8/80") -> Đạt
A40: 4.2.2 | B40: 3 | C40: API kho thuốc, lô và cảnh báo | D40: API kho | E40: BE | F40: 40 | G40: =IF(AND(F40>=8,F40<=80),"Đạt","Vi phạm 8/80") -> Đạt
A41: 4.2.3 | B41: 3 | C41: API đơn hàng và khách hàng | D41: API đơn hàng, khách hàng | E41: BE | F41: 32 | G41: =IF(AND(F41>=8,F41<=80),"Đạt","Vi phạm 8/80") -> Đạt
...

Sheet ChiPhi
A1: ƯỚC LƯỢNG CHI PHÍ DỰ ÁN (VND)
A2: Đơn giá là giả định của nhóm (chi phí công ty gồm lương + bảo hiểm, tính theo giờ), không phải báo giá thật.
A4: Vai trò | B4: Diễn giải | C4: Đơn giá (VND/giờ) | D4: Giờ công (từ WBS) | E4: Thành tiền (VND)
A5: PM | B5: Quản lý dự án | C5: 180000 | D5: =SUMIFS(WBS!$F$5:$F$78,WBS!$E$5:$E$78,A5,WBS!$B$5:$B$78,3) -> 156 | E5: =C5*D5 -> 28080000
A6: BA | B6: Phân tích nghiệp vụ | C6: 150000 | D6: =SUMIFS(WBS!$F$5:$F$78,WBS!$E$5:$E$78,A6,WBS!$B$5:$B$78,3) -> 144 | E6: =C6*D6 -> 21600000
A7: BE | B7: Lập trình viên backend | C7: 160000 | D7: =SUMIFS(WBS!$F$5:$F$78,WBS!$E$5:$E$78,A7,WBS!$B$5:$B$78,3) -> 460 | E7: =C7*D7 -> 73600000
A8: FE | B8: Lập trình viên frontend (kiêm thiết kế UI) | C8: 150000 | D8: =SUMIFS(WBS!$F$5:$F$78,WBS!$E$5:$E$78,A8,WBS!$B$5:$B$78,3) -> 444 | E8: =C8*D8 -> 66600000
A9: QA | B9: Kiểm thử viên | C9: 120000 | D9: =SUMIFS(WBS!$F$5:$F$78,WBS!$E$5:$E$78,A9,WBS!$B$5:$B$78,3) -> 160 | E9: =C9*D9 -> 19200000
A10: Cộng nhân công | D10: =SUM(D5:D9) -> 1364 | E10: =SUM(E5:E9) -> 209080000
B11: Kiểm tra: giờ công khớp tổng WBS? | D11: =IF(D10=WBS!$F$80,"Khớp","Lệch") -> Khớp
A13: Chi phí khác | B13: Diễn giải | C13: Số lượng | D13: Đơn giá (VND) | E13: Thành tiền (VND)
A14: Hosting | B14: Máy chủ ảo (VPS) năm đầu, 12 tháng | C14: 12 | D14: 500000 | E14: =C14*D14 -> 6000000
A15: Tên miền + SSL | B15: Tên miền .vn và chứng chỉ SSL 1 năm | C15: 1 | D15: 1000000 | E15: =C15*D15 -> 1000000
A16: Đào tạo | B16: In tài liệu, đi lại cho 2 buổi đào tạo | C16: 2 | D16: 1500000 | E16: =C16*D16 -> 3000000
A17: Cộng chi phí khác | E17: =SUM(E14:E16) -> 10000000
A19: Chi phí trực tiếp | E19: =E10+E17 -> 219080000
A20: Tỷ lệ dự phòng | B20: Dự phòng rủi ro (contingency reserve) | C20: 0.1 | E20: =E19*C20 -> 21908000
A21: TỔNG DỰ TOÁN | E21: =E19+E20 -> 240988000
A22: Ngân sách được duyệt | B22: Theo tài liệu yêu cầu khách hàng | E22: 250000000
A23: Còn lại | E23: =E22-E21 -> 9012000
A24: Tỷ lệ sử dụng | E24: =E21/E22 -> 0.963952
A25: Kết luận | E25: =IF(E21<=E22,"Trong ngân sách","VƯỢT NGÂN SÁCH") -> Trong ngân sách

Sheet PERT
A1: ƯỚC LƯỢNG PERT 3 ĐIỂM & ĐƯỜNG GĂNG (CPM) – đơn vị: ngày làm việc
A3: Ngày khởi động | C3: 46300 | D3: Ngày làm việc thứ 1 = ngày khởi động. Chưa trừ ngày nghỉ lễ (giai đoạn 10–12/2026 không có ngày lễ).
A4: Hạn chót go-live | C4: 46387
A5: Số ngày làm việc tới hạn | C5: =NETWORKDAYS(C3,C4) -> 64
A8: Mã | B8: Hoạt động | C8: WBS liên quan | D8: Hoạt động trước | E8: O | F8: M | G8: P | H8: TE = (O+4M+P)/6 | I8: σ = (P−O)/6 | J8: σ² | K8: ES | L8: EF | M8: LS | N8: LF | O8: Slack | P8: Găng? | Q8: Ngày bắt đầu | R8: Ngày kết thúc | S8: TE theo AI (nhóm nhập) | T8: Chênh lệch Excel − AI
A9: A | B9: Khởi động và lập kế hoạch (Charter, WBS, lịch) | C9: 1.1, 1.2 | D9: — | E9: 3 | F9: 5 | G9: 8 | H9: =(E9+4*F9+G9)/6 -> 5.1666667 | I9: =(G9-E9)/6 -> 0.83333333 | J9: =I9^2 -> 0.69444444 | K9: =0 -> 0 | L9: =K9+H9 -> 5.1666667 | M9: =N9-H9 -> -1.0658141e-14 | N9: =MIN(M10) -> 5.1666667 | O9: =M9-K9 -> -1.0658141e-14 | P9: =IF(ABS(O9)<0.005,"Găng","") -> Găng | Q9: =WORKDAY($C$3,INT(K9)) -> 46300 | R9: =WORKDAY($C$3,ROUNDUP(L9,0)-1) -> 46307 | S9: =31/6 -> 5.1666667 | T9: =IF(S9="","",H9-S9) -> 0
A10: B | B10: Khảo sát nghiệp vụ và dữ liệu hiện có | C10: 2.1 | D10: A | E10: 4 | F10: 6 | G10: 10 | H10: =(E10+4*F10+G10)/6 -> 6.3333333 | I10: =(G10-E10)/6 -> 1 | J10: =I10^2 -> 1 | K10: =MAX(L9) -> 5.1666667 | L10: =K10+H10 -> 11.5 | M10: =N10-H10 -> 5.1666667 | N10: =MIN(M11) -> 11.5 | O10: =M10-K10 -> -1.0658141e-14 | P10: =IF(ABS(O10)<0.005,"Găng","") -> Găng | Q10: =WORKDAY($C$3,INT(K10)) -> 46307 | R10: =WORKDAY($C$3,ROUNDUP(L10,0)-1) -> 46315 | S10: =38/6 -> 6.3333333 | T10: =IF(S10="","",H10-S10) -> 0
A11: C | B11: Đặc tả yêu cầu (SRS) và phê duyệt | C11: 2.2 | D11: B | E11: 4 | F11: 6 | G11: 9 | H11: =(E11+4*F11+G11)/6 -> 6.1666667 | I11: =(G11-E11)/6 -> 0.83333333 | J11: =I11^2 -> 0.69444444 | K11: =MAX(L10) -> 11.5 | L11: =K11+H11 -> 17.666667 | M11: =N11-H11 -> 11.5 | N11: =MIN(M12,M13,M20) -> 17.666667 | O11: =M11-K11 -> 0 | P11: =IF(ABS(O11)<0.005,"Găng","") -> Găng | Q11: =WORKDAY($C$3,INT(K11)) -> 46315 | R11: =WORKDAY($C$3,ROUNDUP(L11,0)-1) -> 46323 | S11: =37/6 -> 6.1666667 | T11: =IF(S11="","",H11-S11) -> 0
A12: D | B12: Thiết kế kiến trúc, CSDL, API | C12: 3.1 | D12: C | E12: 4 | F12: 6 | G12: 10 | H12: =(E12+4*F12+G12)/6 -> 6.3333333 | I12: =(G12-E12)/6 -> 1 | J12: =I12^2 -> 1 | K12: =MAX(L11) -> 17.666667 | L12: =K12+H12 -> 24 | M12: =N12-H12 -> 18.166667 | N12: =MIN(M14) -> 24.5 | O12: =M12-K12 -> 0.5 | P12: =IF(ABS(O12)<0.005,"Găng","") | Q12: =WORKDAY($C$3,INT(K12)) -> 46323 | R12: =WORKDAY($C$3,ROUNDUP(L12,0)-1) -> 46331 | S12: =38/6 -> 6.3333333 | T12: =IF(S12="","",H12-S12) -> 0
A13: E | B13: Thiết kế giao diện (wireframe, mockup) | C13: 3.2 | D13: C | E13: 5 | F13: 8 | G13: 12 | H13: =(E13+4*F13+G13)/6 -> 8.1666667 | I13: =(G13-E13)/6 -> 1.1666667 | J13: =I13^2 -> 1.3611111 | K13: =MAX(L11) -> 17.666667 | L13: =K13+H13 -> 25.833333 | M13: =N13-H13 -> 17.666667 | N13: =MIN(M17) -> 25.833333 | O13: =M13-K13 -> 0 | P13: =IF(ABS(O13)<0.005,"Găng","") -> Găng | Q13: =WORKDAY($C$3,INT(K13)) -> 46323 | R13: =WORKDAY($C$3,ROUNDUP(L13,0)-1) -> 46335 | S13: =49/6 -> 8.1666667 | T13: =IF(S13="","",H13-S13) -> 0
A14: F | B14: Nền tảng backend, xác thực và phân quyền | C14: 4.1 | D14: D | E14: 3 | F14: 5 | G14: 8 | H14: =(E14+4*F14+G14)/6 -> 5.1666667 | I14: =(G14-E14)/6 -> 0.83333333 | J14: =I14^2 -> 0.69444444 | K14: =MAX(L12) -> 24 | L14: =K14+H14 -> 29.166667 | M14: =N14-H14 -> 24.5 | N14: =MIN(M15,M16,M18) -> 29.666667 | O14: =M14-K14 -> 0.5 | P14: =IF(ABS(O14)<0.005,"Găng","") | Q14: =WORKDAY($C$3,INT(K14)) -> 46332 | R14: =WORKDAY($C$3,ROUNDUP(L14,0)-1) -> 46339 | S14: =31/6 -> 5.1666667 | T14: =IF(S14="","",H14-S14) -> 0
A15: G | B15: Phát triển API nghiệp vụ | C15: 4.2 | D15: F | E15: 14 | F15: 18 | G15: 26 | H15: =(E15+4*F15+G15)/6 -> 18.666667 | I15: =(G15-E15)/6 -> 2 | J15: =I15^2 -> 4 | K15: =MAX(L14) -> 29.166667 | L15: =K15+H15 -> 47.833333 | M15: =N15-H15 -> 29.666667 | N15: =MIN(M19) -> 48.333333 | O15: =M15-K15 -> 0.5 | P15: =IF(ABS(O15)<0.005,"Găng","") | Q15: =WORKDAY($C$3,INT(K15)) -> 46339 | R15: =WORKDAY($C$3,ROUNDUP(L15,0)-1) -> 46365 | S15: =112/6 -> 18.666667 | T15: =IF(S15="","",H15-S15) -> 0
A16: H | B16: Tích hợp phần mềm bán hàng, chuyển đổi dữ liệu | C16: 4.4 | D16: F | E16: 8 | F16: 12 | G16: 20 | H16: =(E16+4*F16+G16)/6 -> 12.666667 | I16: =(G16-E16)/6 -> 2 | J16: =I16^2 -> 4 | K16: =MAX(L14) -> 29.166667 | L16: =K16+H16 -> 41.833333 | M16: =N16-H16 -> 40.833333 | N16: =MIN(M21) -> 53.5 | O16: =M16-K16 -> 11.666667 | P16: =IF(ABS(O16)<0.005,"Găng","") | Q16: =WORKDAY($C$3,INT(K16)) -> 46339 | R16: =WORKDAY($C$3,ROUNDUP(L16,0)-1) -> 46357 | S16: =76/6 -> 12.666667 | T16: =IF(S16="","",H16-S16) -> 0
A17: I | B17: Khung giao diện và thư viện component | C17: 5.1 | D17: E | E17: 5 | F17: 7 | G17: 10 | H17: =(E17+4*F17+G17)/6 -> 7.1666667 | I17: =(G17-E17)/6 -> 0.83333333 | J17: =I17^2 -> 0.69444444 | K17: =MAX(L13) -> 25.833333 | L17: =K17+H17 -> 33 | M17: =N17-H17 -> 25.833333 | N17: =MIN(M18) -> 33 | O17: =M17-K17 -> 0 | P17: =IF(ABS(O17)<0.005,"Găng","") -> Găng | Q17: =WORKDAY($C$3,INT(K17)) -> 46335 | R17: =WORKDAY($C$3,ROUNDUP(L17,0)-1) -> 46344 | S17: =43/6 -> 7.1666667 | T17: =IF(S17="","",H17-S17) -> 0
A18: J | B18: Phát triển các màn hình nghiệp vụ | C18: 5.2, 5.3 | D18: I, F | E18: 15 | F18: 20 | G18: 28 | H18: =(E18+4*F18+G18)/6 -> 20.5 | I18: =(G18-E18)/6 -> 2.1666667 | J18: =I18^2 -> 4.6944444 | K18: =MAX(L17,L14) -> 33 | L18: =K18+H18 -> 53.5 | M18: =N18-H18 -> 33 | N18: =MIN(M21) -> 53.5 | O18: =M18-K18 -> 0 | P18: =IF(ABS(O18)<0.005,"Găng","") -> Găng | Q18: =WORKDAY($C$3,INT(K18)) -> 46345 | R18: =WORKDAY($C$3,ROUNDUP(L18,0)-1) -> 46373 | S18: =123/6 -> 20.5 | T18: =IF(S18="","",H18-S18) -> 0
A19: K | B19: Chức năng xuất báo cáo CSV/PDF | C19: 4.3 | D19: G | E19: 3 | F19: 5 | G19: 8 | H19: =(E19+4*F19+G19)/6 -> 5.1666667 | I19: =(G19-E19)/6 -> 0.83333333 | J19: =I19^2 -> 0.69444444 | K19: =MAX(L15) -> 47.833333 | L19: =K19+H19 -> 53 | M19: =N19-H19 -> 48.333333 | N19: =MIN(M21) -> 53.5 | O19: =M19-K19 -> 0.5 | P19: =IF(ABS(O19)<0.005,"Găng","") | Q19: =WORKDAY($C$3,INT(K19)) -> 46365 | R19: =WORKDAY($C$3,ROUNDUP(L19,0)-1) -> 46372 | S19: =31/6 -> 5.1666667 | T19: =IF(S19="","",H19-S19) -> 0
A20: L | B20: Kế hoạch kiểm thử và test case | C20: 6.1 | D20: C | E20: 3 | F20: 4 | G20: 6 | H20: =(E20+4*F20+G20)/6 -> 4.1666667 | I20: =(G20-E20)/6 -> 0.5 | J20: =I20^2 -> 0.25 | K20: =MAX(L11) -> 17.666667 | L20: =K20+H20 -> 21.833333 | M20: =N20-H20 -> 49.333333 | N20: =MIN(M21) -> 53.5 | O20: =M20-K20 -> 31.666667 | P20: =IF(ABS(O20)<0.005,"Găng","") | Q20: =WORKDAY($C$3,INT(K20)) -> 46323 | R20: =WORKDAY($C$3,ROUNDUP(L20,0)-1) -> 46329 | S20: =25/6 -> 4.1666667 | T20: =IF(S20="","",H20-S20) -> 0
A21: M | B21: Kiểm thử hệ thống và sửa lỗi | C21: 6.2 | D21: J, K, H, L | E21: 8 | F21: 12 | G21: 18 | H21: =(E21+4*F21+G21)/6 -> 12.333333 | I21: =(G21-E21)/6 -> 1.6666667 | J21: =I21^2 -> 2.7777778 | K21: =MAX(L18,L19,L16,L20) -> 53.5 | L21: =K21+H21 -> 65.833333 | M21: =N21-H21 -> 53.5 | N21: =MIN(M22) -> 65.833333 | O21: =M21-K21 -> 0 | P21: =IF(ABS(O21)<0.005,"Găng","") -> Găng | Q21: =WORKDAY($C$3,INT(K21)) -> 46373 | R21: =WORKDAY($C$3,ROUNDUP(L21,0)-1) -> 46391 | S21: =74/6 -> 12.333333 | T21: =IF(S21="","",H21-S21) -> 0
A22: N | B22: Kiểm thử chấp nhận (UAT) và nghiệm thu | C22: 6.3 | D22: M | E22: 3 | F22: 5 | G22: 8 | H22: =(E22+4*F22+G22)/6 -> 5.1666667 | I22: =(G22-E22)/6 -> 0.83333333 | J22: =I22^2 -> 0.69444444 | K22: =MAX(L21) -> 65.833333 | L22: =K22+H22 -> 71 | M22: =N22-H22 -> 65.833333 | N22: =MIN(M23) -> 71 | O22: =M22-K22 -> 0 | P22: =IF(ABS(O22)<0.005,"Găng","") -> Găng | Q22: =WORKDAY($C$3,INT(K22)) -> 46391 | R22: =WORKDAY($C$3,ROUNDUP(L22,0)-1) -> 46398 | S22: =31/6 -> 5.1666667 | T22: =IF(S22="","",H22-S22) -> 0
A23: O | B23: Go-live, đào tạo người dùng | C23: 7.1, 7.2 | D23: N | E23: 3 | F23: 4 | G23: 7 | H23: =(E23+4*F23+G23)/6 -> 4.3333333 | I23: =(G23-E23)/6 -> 0.66666667 | J23: =I23^2 -> 0.44444444 | K23: =MAX(L22) -> 71 | L23: =K23+H23 -> 75.333333 | M23: =N23-H23 -> 71 | N23: =$C$26 -> 75.333333 | O23: =M23-K23 -> 0 | P23: =IF(ABS(O23)<0.005,"Găng","") -> Găng | Q23: =WORKDAY($C$3,INT(K23)) -> 46399 | R23: =WORKDAY($C$3,ROUNDUP(L23,0)-1) -> 46405 | S23: =26/6 -> 4.3333333 | T23: =IF(S23="","",H23-S23) -> 0
A25: KẾT QUẢ
A26: Thời gian dự án kỳ vọng T (ngày làm việc) | C26: =MAX(L9:L23) -> 75.333333
A27: Đường găng | C27: =LEFT(IF(P9="Găng","A → ","")&IF(P10="Găng","B → ","")&IF(P11="Găng","C → ","")&IF(P12="Găng","D → ","")&IF(P13="Găng","E → ","")&IF(P14="Găng","F → ","")&IF(P15="Găng","G → ","")&IF(P16="Găng","H → ","")&IF(P17="Găng","I → ","")&IF(P18="Găng","J → ","")&IF(P19="Găng","K → ","")&IF(P20="Găng","L → ","")&IF(P21="Găng","M → ","")&IF(P22="Găng","N → ","")&IF(P23="Găng","O → ",""),LEN(IF(P9="Găng","A → ","")&IF(P10="Găng","B → ","")&IF(P11="Găng","C → ","")&IF(P12="Găng","D → ","")&IF(P13="Găng","E → ","")&IF(P14="Găng","F → ","")&IF(P15="Găng","G → ","")&IF(P16="Găng","H → ","")&IF(P17="Găng","I → ","")&IF(P18="Găng","J → ","")&IF(P19="Găng","K → ","")&IF(P20="Găng","L → ","")&IF(P21="Găng","M → ","")&IF(P22="Găng","N → ","")&IF(P23="Găng","O → ",""))-3) -> A → B → C → E → I → J → M → N → O
A28: Tổng phương sai đường găng Σσ² | C28: =SUMIF(P9:P23,"Găng",J9:J23) -> 13.055556
A29: Độ lệch chuẩn đường găng σ | C29: =SQRT(C28) -> 3.6132472
A30: Số ngày làm việc tới hạn chót | C30: =C5 -> 64
A31: Chênh lệch T − hạn chót (ngày; dương = trễ) | C31: =C26-C30 -> 11.333333
A32: Z = (hạn chót − T) / σ | C32: =(C30-C26)/C29 -> -3.1366061
A33: Xác suất hoàn thành đúng hạn P(Z) | C33: =NORMSDIST(C32) -> 0.00085457789
A34: Ngày kết thúc dự kiến (T) | C34: =WORKDAY(C3,ROUNDUP(C26,0)-1) -> 46405
A35: Kết luận | C35: =IF(C31<=0,"Kịp hạn chót","TRỄ HẠN – cần nén lịch (crashing / fast-tracking)") -> TRỄ HẠN – cần nén lịch (crashing / fast-tracking)

Sheet Gantt
A1: BIỂU ĐỒ GANTT (tự vẽ từ sheet PERT)
A2: Đỏ = hoạt động găng · Xanh = không găng · Cột cam = ngày làm việc cuối cùng trước hạn chót. Mỗi cột = 1 ngày làm việc.
F4: =WORKDAY(PERT!$C$3,0) -> 46300 | G4: =WORKDAY(PERT!$C$3,1) -> 46301 | H4: =WORKDAY(PERT!$C$3,2) -> 46302 | I4: =WORKDAY(PERT!$C$3,3) -> 46303 | J4: =WORKDAY(PERT!$C$3,4) -> 46304 | K4: =WORKDAY(PERT!$C$3,5) -> 46307 | L4: =WORKDAY(PERT!$C$3,6) -> 46308 | M4: =WORKDAY(PERT!$C$3,7) -> 46309 | N4: =WORKDAY(PERT!$C$3,8) -> 46310 | O4: =WORKDAY(PERT!$C$3,9) -> 46311 | P4: =WORKDAY(PERT!$C$3,10) -> 46314 | Q4: =WORKDAY(PERT!$C$3,11) -> 46315 | R4: =WORKDAY(PERT!$C$3,12) -> 46316 | S4: =WORKDAY(PERT!$C$3,13) -> 46317 | T4: =WORKDAY(PERT!$C$3,14) -> 46318 | U4: =WORKDAY(PERT!$C$3,15) -> 46321 | V4: =WORKDAY(PERT!$C$3,16) -> 46322 | W4: =WORKDAY(PERT!$C$3,17) -> 46323 | X4: =WORKDAY(PERT!$C$3,18) -> 46324 | Y4: =WORKDAY(PERT!$C$3,19) -> 46325 | Z4: =WORKDAY(PERT!$C$3,20) -> 46328 | AA4: =WORKDAY(PERT!$C$3,21) -> 46329 | AB4: =WORKDAY(PERT!$C$3,22) -> 46330 | AC4: =WORKDAY(PERT!$C$3,23) -> 46331 | AD4: =WORKDAY(PERT!$C$3,24) -> 46332 | AE4: =WORKDAY(PERT!$C$3,25) -> 46335 | AF4: =WORKDAY(PERT!$C$3,26) -> 46336 | AG4: =WORKDAY(PERT!$C$3,27) -> 46337 | AH4: =WORKDAY(PERT!$C$3,28) -> 46338 | AI4: =WORKDAY(PERT!$C$3,29) -> 46339 | AJ4: =WORKDAY(PERT!$C$3,30) -> 46342 | AK4: =WORKDAY(PERT!$C$3,31) -> 46343 | AL4: =WORKDAY(PERT!$C$3,32) -> 46344 | AM4: =WORKDAY(PERT!$C$3,33) -> 46345 | AN4: =WORKDAY(PERT!$C$3,34) -> 46346 | AO4: =WORKDAY(PERT!$C$3,35) -> 46349 | AP4: =WORKDAY(PERT!$C$3,36) -> 46350 | AQ4: =WORKDAY(PERT!$C$3,37) -> 46351 | AR4: =WORKDAY(PERT!$C$3,38) -> 46352 | AS4: =WORKDAY(PERT!$C$3,39) -> 46353 | AT4: =WORKDAY(PERT!$C$3,40) -> 46356 | AU4: =WORKDAY(PERT!$C$3,41) -> 46357 | AV4: =WORKDAY(PERT!$C$3,42) -> 46358 | AW4: =WORKDAY(PERT!$C$3,43) -> 46359 | AX4: =WORKDAY(PERT!$C$3,44) -> 46360 | AY4: =WORKDAY(PERT!$C$3,45) -> 46363 | AZ4: =WORKDAY(PERT!$C$3,46) -> 46364 | BA4: =WORKDAY(PERT!$C$3,47) -> 46365 | BB4: =WORKDAY(PERT!$C$3,48) -> 46366 | BC4: =WORKDAY(PERT!$C$3,49) -> 46367 | BD4: =WORKDAY(PERT!$C$3,50) -> 46370 | BE4: =WORKDAY(PERT!$C$3,51) -> 46371 | BF4: =WORKDAY(PERT!$C$3,52) -> 46372 | BG4: =WORKDAY(PERT!$C$3,53) -> 46373 | BH4: =WORKDAY(PERT!$C$3,54) -> 46374 | BI4: =WORKDAY(PERT!$C$3,55) -> 46377 | BJ4: =WORKDAY(PERT!$C$3,56) -> 46378 | BK4: =WORKDAY(PERT!$C$3,57) -> 46379 | BL4: =WORKDAY(PERT!$C$3,58) -> 46380 | BM4: =WORKDAY(PERT!$C$3,59) -> 46381 | BN4: =WORKDAY(PERT!$C$3,60) -> 46384 | BO4: =WORKDAY(PERT!$C$3,61) -> 46385 | BP4: =WORKDAY(PERT!$C$3,62) -> 46386 | BQ4: =WORKDAY(PERT!$C$3,63) -> 46387 | BR4: =WORKDAY(PERT!$C$3,64) -> 46388 | BS4: =WORKDAY(PERT!$C$3,65) -> 46391 | BT4: =WORKDAY(PERT!$C$3,66) -> 46392 | BU4: =WORKDAY(PERT!$C$3,67) -> 46393 | BV4: =WORKDAY(PERT!$C$3,68) -> 46394 | BW4: =WORKDAY(PERT!$C$3,69) -> 46395 | BX4: =WORKDAY(PERT!$C$3,70) -> 46398 | BY4: =WORKDAY(PERT!$C$3,71) -> 46399 | BZ4: =WORKDAY(PERT!$C$3,72) -> 46400 | CA4: =WORKDAY(PERT!$C$3,73) -> 46401 | CB4: =WORKDAY(PERT!$C$3,74) -> 46402 | CC4: =WORKDAY(PERT!$C$3,75) -> 46405 | CD4: =WORKDAY(PERT!$C$3,76) -> 46406 | CE4: =WORKDAY(PERT!$C$3,77) -> 46407 | CF4: =WORKDAY(PERT!$C$3,78) -> 46408 | CG4: =WORKDAY(PERT!$C$3,79) -> 46409 | CH4: =WORKDAY(PERT!$C$3,80) -> 46412 | CI4: =WORKDAY(PERT!$C$3,81) -> 46413 | CJ4: =WORKDAY(PERT!$C$3,82) -> 46414 | CK4: =WORKDAY(PERT!$C$3,83) -> 46415 | CL4: =WORKDAY(PERT!$C$3,84) -> 46416
A5: Mã | B5: Hoạt động | C5: ES | D5: EF | E5: Găng? | F5: 1 | G5: 2 | H5: 3 | I5: 4 | J5: 5 | K5: 6 | L5: 7 | M5: 8 | N5: 9 | O5: 10 | P5: 11 | Q5: 12 | R5: 13 | S5: 14 | T5: 15 | U5: 16 | V5: 17 | W5: 18 | X5: 19 | Y5: 20 | Z5: 21 | AA5: 22 | AB5: 23 | AC5: 24 | AD5: 25 | AE5: 26 | AF5: 27 | AG5: 28 | AH5: 29 | AI5: 30 | AJ5: 31 | AK5: 32 | AL5: 33 | AM5: 34 | AN5: 35 | AO5: 36 | AP5: 37 | AQ5: 38 | AR5: 39 | AS5: 40 | AT5: 41 | AU5: 42 | AV5: 43 | AW5: 44 | AX5: 45 | AY5: 46 | AZ5: 47 | BA5: 48 | BB5: 49 | BC5: 50 | BD5: 51 | BE5: 52 | BF5: 53 | BG5: 54 | BH5: 55 | BI5: 56 | BJ5: 57 | BK5: 58 | BL5: 59 | BM5: 60 | BN5: 61 | BO5: 62 | BP5: 63 | BQ5: 64 | BR5: 65 | BS5: 66 | BT5: 67 | BU5: 68 | BV5: 69 | BW5: 70 | BX5: 71 | BY5: 72 | BZ5: 73 | CA5: 74 | CB5: 75 | CC5: 76 | CD5: 77 | CE5: 78 | CF5: 79 | CG5: 80 | CH5: 81 | CI5: 82 | CJ5: 83 | CK5: 84 | CL5: 85
A6: =PERT!A9 -> A | B6: =PERT!B9 -> Khởi động và lập kế hoạch (Charter, WBS, lịch) | C6: =PERT!K9 -> 0 | D6: =PERT!L9 -> 5.1666667 | E6: =PERT!P9 -> Găng | F6: =IF(AND(F$5>$C6,F$5-1<$D6),1,"") -> 1 | G6: =IF(AND(G$5>$C6,G$5-1<$D6),1,"") -> 1 | H6: =IF(AND(H$5>$C6,H$5-1<$D6),1,"") -> 1 | I6: =IF(AND(I$5>$C6,I$5-1<$D6),1,"") -> 1 | J6: =IF(AND(J$5>$C6,J$5-1<$D6),1,"") -> 1 | K6: =IF(AND(K$5>$C6,K$5-1<$D6),1,"") -> 1 | L6: =IF(AND(L$5>$C6,L$5-1<$D6),1,"") | M6: =IF(AND(M$5>$C6,M$5-1<$D6),1,"") | ... CL6: =IF(AND(CL$5>$C6,CL$5-1<$D6),1,"")
A7: =PERT!A10 -> B | B7: =PERT!B10 -> Khảo sát nghiệp vụ và dữ liệu hiện có | C7: =PERT!K10 -> 5.1666667 | D7: =PERT!L10 -> 11.5 | E7: =PERT!P10 -> Găng | F7: =IF(AND(F$5>$C7,F$5-1<$D7),1,"") | G7: =IF(AND(G$5>$C7,G$5-1<$D7),1,"") | H7: =IF(AND(H$5>$C7,H$5-1<$D7),1,"") | I7: =IF(AND(I$5>$C7,I$5-1<$D7),1,"") | J7: =IF(AND(J$5>$C7,J$5-1<$D7),1,"") | K7: =IF(AND(K$5>$C7,K$5-1<$D7),1,"") -> 1 | L7: =IF(AND(L$5>$C7,L$5-1<$D7),1,"") -> 1 | M7: =IF(AND(M$5>$C7,M$5-1<$D7),1,"") -> 1 | ... CL7: =IF(AND(CL$5>$C7,CL$5-1<$D7),1,"")
A8: =PERT!A11 -> C | B8: =PERT!B11 -> Đặc tả yêu cầu (SRS) và phê duyệt | C8: =PERT!K11 -> 11.5 | D8: =PERT!L11 -> 17.666667 | E8: =PERT!P11 -> Găng | F8: =IF(AND(F$5>$C8,F$5-1<$D8),1,"") | G8: =IF(AND(G$5>$C8,G$5-1<$D8),1,"") | H8: =IF(AND(H$5>$C8,H$5-1<$D8),1,"") | I8: =IF(AND(I$5>$C8,I$5-1<$D8),1,"") | J8: =IF(AND(J$5>$C8,J$5-1<$D8),1,"") | K8: =IF(AND(K$5>$C8,K$5-1<$D8),1,"") | L8: =IF(AND(L$5>$C8,L$5-1<$D8),1,"") | M8: =IF(AND(M$5>$C8,M$5-1<$D8),1,"") | ... CL8: =IF(AND(CL$5>$C8,CL$5-1<$D8),1,"")
A9: =PERT!A12 -> D | B9: =PERT!B12 -> Thiết kế kiến trúc, CSDL, API | C9: =PERT!K12 -> 17.666667 | D9: =PERT!L12 -> 24 | E9: =PERT!P12 | F9: =IF(AND(F$5>$C9,F$5-1<$D9),1,"") | G9: =IF(AND(G$5>$C9,G$5-1<$D9),1,"") | H9: =IF(AND(H$5>$C9,H$5-1<$D9),1,"") | I9: =IF(AND(I$5>$C9,I$5-1<$D9),1,"") | J9: =IF(AND(J$5>$C9,J$5-1<$D9),1,"") | K9: =IF(AND(K$5>$C9,K$5-1<$D9),1,"") | L9: =IF(AND(L$5>$C9,L$5-1<$D9),1,"") | M9: =IF(AND(M$5>$C9,M$5-1<$D9),1,"") | ... CL9: =IF(AND(CL$5>$C9,CL$5-1<$D9),1,"")
A10: =PERT!A13 -> E | B10: =PERT!B13 -> Thiết kế giao diện (wireframe, mockup) | C10: =PERT!K13 -> 17.666667 | D10: =PERT!L13 -> 25.833333 | E10: =PERT!P13 -> Găng | F10: =IF(AND(F$5>$C10,F$5-1<$D10),1,"") | G10: =IF(AND(G$5>$C10,G$5-1<$D10),1,"") | H10: =IF(AND(H$5>$C10,H$5-1<$D10),1,"") | I10: =IF(AND(I$5>$C10,I$5-1<$D10),1,"") | J10: =IF(AND(J$5>$C10,J$5-1<$D10),1,"") | K10: =IF(AND(K$5>$C10,K$5-1<$D10),1,"") | L10: =IF(AND(L$5>$C10,L$5-1<$D10),1,"") | M10: =IF(AND(M$5>$C10,M$5-1<$D10),1,"") | ... CL10: =IF(AND(CL$5>$C10,CL$5-1<$D10),1,"")
A11: =PERT!A14 -> F | B11: =PERT!B14 -> Nền tảng backend, xác thực và phân quyền | C11: =PERT!K14 -> 24 | D11: =PERT!L14 -> 29.166667 | E11: =PERT!P14 | F11: =IF(AND(F$5>$C11,F$5-1<$D11),1,"") | G11: =IF(AND(G$5>$C11,G$5-1<$D11),1,"") | H11: =IF(AND(H$5>$C11,H$5-1<$D11),1,"") | I11: =IF(AND(I$5>$C11,I$5-1<$D11),1,"") | J11: =IF(AND(J$5>$C11,J$5-1<$D11),1,"") | K11: =IF(AND(K$5>$C11,K$5-1<$D11),1,"") | L11: =IF(AND(L$5>$C11,L$5-1<$D11),1,"") | M11: =IF(AND(M$5>$C11,M$5-1<$D11),1,"") | ... CL11: =IF(AND(CL$5>$C11,CL$5-1<$D11),1,"")
A12: =PERT!A15 -> G | B12: =PERT!B15 -> Phát triển API nghiệp vụ | C12: =PERT!K15 -> 29.166667 | D12: =PERT!L15 -> 47.833333 | E12: =PERT!P15 | F12: =IF(AND(F$5>$C12,F$5-1<$D12),1,"") | G12: =IF(AND(G$5>$C12,G$5-1<$D12),1,"") | H12: =IF(AND(H$5>$C12,H$5-1<$D12),1,"") | I12: =IF(AND(I$5>$C12,I$5-1<$D12),1,"") | J12: =IF(AND(J$5>$C12,J$5-1<$D12),1,"") | K12: =IF(AND(K$5>$C12,K$5-1<$D12),1,"") | L12: =IF(AND(L$5>$C12,L$5-1<$D12),1,"") | M12: =IF(AND(M$5>$C12,M$5-1<$D12),1,"") | ... CL12: =IF(AND(CL$5>$C12,CL$5-1<$D12),1,"")
A13: =PERT!A16 -> H | B13: =PERT!B16 -> Tích hợp phần mềm bán hàng, chuyển đổi dữ liệu | C13: =PERT!K16 -> 29.166667 | D13: =PERT!L16 -> 41.833333 | E13: =PERT!P16 | F13: =IF(AND(F$5>$C13,F$5-1<$D13),1,"") | G13: =IF(AND(G$5>$C13,G$5-1<$D13),1,"") | H13: =IF(AND(H$5>$C13,H$5-1<$D13),1,"") | I13: =IF(AND(I$5>$C13,I$5-1<$D13),1,"") | J13: =IF(AND(J$5>$C13,J$5-1<$D13),1,"") | K13: =IF(AND(K$5>$C13,K$5-1<$D13),1,"") | L13: =IF(AND(L$5>$C13,L$5-1<$D13),1,"") | M13: =IF(AND(M$5>$C13,M$5-1<$D13),1,"") | ... CL13: =IF(AND(CL$5>$C13,CL$5-1<$D13),1,"")
A14: =PERT!A17 -> I | B14: =PERT!B17 -> Khung giao diện và thư viện component | C14: =PERT!K17 -> 25.833333 | D14: =PERT!L17 -> 33 | E14: =PERT!P17 -> Găng | F14: =IF(AND(F$5>$C14,F$5-1<$D14),1,"") | G14: =IF(AND(G$5>$C14,G$5-1<$D14),1,"") | H14: =IF(AND(H$5>$C14,H$5-1<$D14),1,"") | I14: =IF(AND(I$5>$C14,I$5-1<$D14),1,"") | J14: =IF(AND(J$5>$C14,J$5-1<$D14),1,"") | K14: =IF(AND(K$5>$C14,K$5-1<$D14),1,"") | L14: =IF(AND(L$5>$C14,L$5-1<$D14),1,"") | M14: =IF(AND(M$5>$C14,M$5-1<$D14),1,"") | ... CL14: =IF(AND(CL$5>$C14,CL$5-1<$D14),1,"")
A15: =PERT!A18 -> J | B15: =PERT!B18 -> Phát triển các màn hình nghiệp vụ | C15: =PERT!K18 -> 33 | D15: =PERT!L18 -> 53.5 | E15: =PERT!P18 -> Găng | F15: =IF(AND(F$5>$C15,F$5-1<$D15),1,"") | G15: =IF(AND(G$5>$C15,G$5-1<$D15),1,"") | H15: =IF(AND(H$5>$C15,H$5-1<$D15),1,"") | I15: =IF(AND(I$5>$C15,I$5-1<$D15),1,"") | J15: =IF(AND(J$5>$C15,J$5-1<$D15),1,"") | K15: =IF(AND(K$5>$C15,K$5-1<$D15),1,"") | L15: =IF(AND(L$5>$C15,L$5-1<$D15),1,"") | M15: =IF(AND(M$5>$C15,M$5-1<$D15),1,"") | ... CL15: =IF(AND(CL$5>$C15,CL$5-1<$D15),1,"")
A16: =PERT!A19 -> K | B16: =PERT!B19 -> Chức năng xuất báo cáo CSV/PDF | C16: =PERT!K19 -> 47.833333 | D16: =PERT!L19 -> 53 | E16: =PERT!P19 | F16: =IF(AND(F$5>$C16,F$5-1<$D16),1,"") | G16: =IF(AND(G$5>$C16,G$5-1<$D16),1,"") | H16: =IF(AND(H$5>$C16,H$5-1<$D16),1,"") | I16: =IF(AND(I$5>$C16,I$5-1<$D16),1,"") | J16: =IF(AND(J$5>$C16,J$5-1<$D16),1,"") | K16: =IF(AND(K$5>$C16,K$5-1<$D16),1,"") | L16: =IF(AND(L$5>$C16,L$5-1<$D16),1,"") | M16: =IF(AND(M$5>$C16,M$5-1<$D16),1,"") | ... CL16: =IF(AND(CL$5>$C16,CL$5-1<$D16),1,"")
A17: =PERT!A20 -> L | B17: =PERT!B20 -> Kế hoạch kiểm thử và test case | C17: =PERT!K20 -> 17.666667 | D17: =PERT!L20 -> 21.833333 | E17: =PERT!P20 | F17: =IF(AND(F$5>$C17,F$5-1<$D17),1,"") | G17: =IF(AND(G$5>$C17,G$5-1<$D17),1,"") | H17: =IF(AND(H$5>$C17,H$5-1<$D17),1,"") | I17: =IF(AND(I$5>$C17,I$5-1<$D17),1,"") | J17: =IF(AND(J$5>$C17,J$5-1<$D17),1,"") | K17: =IF(AND(K$5>$C17,K$5-1<$D17),1,"") | L17: =IF(AND(L$5>$C17,L$5-1<$D17),1,"") | M17: =IF(AND(M$5>$C17,M$5-1<$D17),1,"") | ... CL17: =IF(AND(CL$5>$C17,CL$5-1<$D17),1,"")
... A20: =PERT!A23 -> O | B20: =PERT!B23 -> Go-live, đào tạo người dùng | C20: =PERT!K23 -> 71 | D20: =PERT!L23 -> 75.333333 | E20: =PERT!P23 -> Găng | F20: =IF(AND(F$5>$C20,F$5-1<$D20),1,"") | G20: =IF(AND(G$5>$C20,G$5-1<$D20),1,"") | H20: =IF(AND(H$5>$C20,H$5-1<$D20),1,"") | I20: =IF(AND(I$5>$C20,I$5-1<$D20),1,"") | J20: =IF(AND(J$5>$C20,J$5-1<$D20),1,"") | K20: =IF(AND(K$5>$C20,K$5-1<$D20),1,"") | L20: =IF(AND(L$5>$C20,L$5-1<$D20),1,"") | M20: =IF(AND(M$5>$C20,M$5-1<$D20),1,"") | ... CL20: =IF(AND(CL$5>$C20,CL$5-1<$D20),1,"")

Sheet NenLich
A1: PHƯƠNG ÁN NÉN LỊCH – fast-tracking + giảm phạm vi (AI đề xuất, nhóm xác nhận)
A2: Cột "Chồng lấn" = số ngày hoạt động được bắt đầu SỚM trước khi các hoạt động trước kết thúc (fast-tracking). ES = MAX(0; MAX(EF hoạt động trước) − Chồng lấn); LF = MIN(LS hoạt động sau + Chồng lấn của hoạt động sau). Sheet PERT giữ nguyên làm lịch gốc.
A4: Mã | B4: Hoạt động | C4: Trước | D4: O | E4: M | F4: P | G4: Chồng lấn | H4: TE | I4: σ² | J4: ES | K4: EF | L4: LS | M4: LF | N4: Slack | O4: Găng? | P4: Thay đổi so với lịch gốc
A5: A | B5: =PERT!B9 -> Khởi động và lập kế hoạch (Charter, WBS, lịch) | C5: — | D5: =PERT!E9 -> 3 | E5: =PERT!F9 -> 5 | F5: =PERT!G9 -> 8 | G5: 0 | H5: =(D5+4*E5+F5)/6 -> 5.1666667 | I5: =((F5-D5)/6)^2 -> 0.69444444 | J5: =0 -> 0 | K5: =J5+H5 -> 5.1666667 | L5: =M5-H5 -> 0 | M5: =MIN(L6+G6) -> 5.1666667 | N5: =L5-J5 -> 0 | O5: =IF(ABS(N5)<0.005,"Găng","") -> Găng
A6: B | B6: =PERT!B10 -> Khảo sát nghiệp vụ và dữ liệu hiện có | C6: A | D6: =PERT!E10 -> 4 | E6: =PERT!F10 -> 6 | F6: =PERT!G10 -> 10 | G6: 0 | H6: =(D6+4*E6+F6)/6 -> 6.3333333 | I6: =((F6-D6)/6)^2 -> 1 | J6: =MAX(0,MAX(K5)-G6) -> 5.1666667 | K6: =J6+H6 -> 11.5 | L6: =M6-H6 -> 5.1666667 | M6: =MIN(L7+G7) -> 11.5 | N6: =L6-J6 -> 0 | O6: =IF(ABS(N6)<0.005,"Găng","") -> Găng
A7: C | B7: =PERT!B11 -> Đặc tả yêu cầu (SRS) và phê duyệt | C7: B | D7: =PERT!E11 -> 4 | E7: =PERT!F11 -> 6 | F7: =PERT!G11 -> 9 | G7: 0 | H7: =(D7+4*E7+F7)/6 -> 6.1666667 | I7: =((F7-D7)/6)^2 -> 0.69444444 | J7: =MAX(0,MAX(K6)-G7) -> 11.5 | K7: =J7+H7 -> 17.666667 | L7: =M7-H7 -> 11.5 | M7: =MIN(L8+G8,L9+G9,L16+G16) -> 17.666667 | N7: =L7-J7 -> 0 | O7: =IF(ABS(N7)<0.005,"Găng","") -> Găng
A8: D | B8: =PERT!B12 -> Thiết kế kiến trúc, CSDL, API | C8: C | D8: =PERT!E12 -> 4 | E8: =PERT!F12 -> 6 | F8: =PERT!G12 -> 10 | G8: 2 | H8: =(D8+4*E8+F8)/6 -> 6.3333333 | I8: =((F8-D8)/6)^2 -> 1 | J8: =MAX(0,MAX(K7)-G8) -> 15.666667 | K8: =J8+H8 -> 22 | L8: =M8-H8 -> 15.666667 | M8: =MIN(L10+G10) -> 22 | N8: =L8-J8 -> 0 | O8: =IF(ABS(N8)<0.005,"Găng","") -> Găng | P8: Fast-tracking: thiết kế kiến trúc bắt đầu khi SRS đã duyệt phần lõi (FR01–FR08)
A9: E | B9: =PERT!B13 -> Thiết kế giao diện (wireframe, mockup) | C9: C | D9: =PERT!E13 -> 5 | E9: =PERT!F13 -> 8 | F9: =PERT!G13 -> 12 | G9: 2 | H9: =(D9+4*E9+F9)/6 -> 8.1666667 | I9: =((F9-D9)/6)^2 -> 1.3611111 | J9: =MAX(0,MAX(K7)-G9) -> 15.666667 | K9: =J9+H9 -> 23.833333 | L9: =M9-H9 -> 16.666667 | M9: =MIN(L13+G13) -> 24.833333 | N9: =L9-J9 -> 1 | O9: =IF(ABS(N9)<0.005,"Găng","") | P9: Fast-tracking: thiết kế giao diện bắt đầu song song giai đoạn cuối SRS
A10: F | B10: =PERT!B14 -> Nền tảng backend, xác thực và phân quyền | C10: D | D10: =PERT!E14 -> 3 | E10: =PERT!F14 -> 5 | F10: =PERT!G14 -> 8 | G10: 0 | H10: =(D10+4*E10+F10)/6 -> 5.1666667 | I10: =((F10-D10)/6)^2 -> 0.69444444 | J10: =MAX(0,MAX(K8)-G10) -> 22 | K10: =J10+H10 -> 27.166667 | L10: =M10-H10 -> 22 | M10: =MIN(L11+G11,L12+G12,L14+G14) -> 27.166667 | N10: =L10-J10 -> 0 | O10: =IF(ABS(N10)<0.005,"Găng","") -> Găng
A11: G | B11: =PERT!B15 -> Phát triển API nghiệp vụ | C11: F | D11: 12 | E11: 15 | F11: 22 | G11: 0 | H11: =(D11+4*E11+F11)/6 -> 15.666667 | I11: =((F11-D11)/6)^2 -> 2.7777778 | J11: =MAX(0,MAX(K10)-G11) -> 27.166667 | K11: =J11+H11 -> 42.833333 | L11: =M11-H11 -> 27.166667 | M11: =MIN(L15+G15) -> 42.833333 | N11: =L11-J11 -> 0 | O11: =IF(ABS(N11)<0.005,"Găng","") -> Găng | P11: Giảm phạm vi: dời API khách hàng thân thiết, nhân viên/ca (FR09–FR10) sang giai đoạn 2
A12: H | B12: =PERT!B16 -> Tích hợp phần mềm bán hàng, chuyển đổi dữ liệu | C12: F | D12: =PERT!E16 -> 8 | E12: =PERT!F16 -> 12 | F12: =PERT!G16 -> 20 | G12: 0 | H12: =(D12+4*E12+F12)/6 -> 12.666667 | I12: =((F12-D12)/6)^2 -> 4 | J12: =MAX(0,MAX(K10)-G12) -> 27.166667 | K12: =J12+H12 -> 39.833333 | L12: =M12-H12 -> 32.333333 | M12: =MIN(L17+G17) -> 45 | N12: =L12-J12 -> 5.1666667 | O12: =IF(ABS(N12)<0.005,"Găng","")
A13: I | B13: =PERT!B17 -> Khung giao diện và thư viện component | C13: E | D13: =PERT!E17 -> 5 | E13: =PERT!F17 -> 7 | F13: =PERT!G17 -> 10 | G13: 0 | H13: =(D13+4*E13+F13)/6 -> 7.1666667 | I13: =((F13-D13)/6)^2 -> 0.69444444 | J13: =MAX(0,MAX(K9)-G13) -> 23.833333 | K13: =J13+H13 -> 31 | L13: =M13-H13 -> 24.833333 | M13: =MIN(L14+G14) -> 32 | N13: =L13-J13 -> 1 | O13: =IF(ABS(N13)<0.005,"Găng","")
A14: J | B14: =PERT!B18 -> Phát triển các màn hình nghiệp vụ | C14: I, F | D14: 12 | E14: 16 | F14: 23 | G14: 3.5 | H14: =(D14+4*E14+F14)/6 -> 16.5 | I14: =((F14-D14)/6)^2 -> 3.3611111 | J14: =MAX(0,MAX(K13,K10)-G14) -> 27.5 | K14: =J14+H14 -> 44 | L14: =M14-H14 -> 28.5 | M14: =MIN(L17+G17) -> 45 | N14: =L14-J14 -> 1 | O14: =IF(ABS(N14)<0.005,"Găng","") | P14: Giảm phạm vi FR09–FR10 + fast-tracking: làm màn hình trên mockup và API giả lập khi khung giao diện xong khoảng 50%
A15: K | B15: =PERT!B19 -> Chức năng xuất báo cáo CSV/PDF | C15: G | D15: =PERT!E19 -> 3 | E15: =PERT!F19 -> 5 | F15: =PERT!G19 -> 8 | G15: 3 | H15: =(D15+4*E15+F15)/6 -> 5.1666667 | I15: =((F15-D15)/6)^2 -> 0.69444444 | J15: =MAX(0,MAX(K11)-G15) -> 39.833333 | K15: =J15+H15 -> 45 | L15: =M15-H15 -> 39.833333 | M15: =MIN(L17+G17) -> 45 | N15: =L15-J15 -> 0 | O15: =IF(ABS(N15)<0.005,"Găng","") -> Găng | P15: Fast-tracking: xuất báo cáo làm khi API doanh thu, tồn kho đã xong (không chờ toàn bộ API)
A16: L | B16: =PERT!B20 -> Kế hoạch kiểm thử và test case | C16: C | D16: =PERT!E20 -> 3 | E16: =PERT!F20 -> 4 | F16: =PERT!G20 -> 6 | G16: 0 | H16: =(D16+4*E16+F16)/6 -> 4.1666667 | I16: =((F16-D16)/6)^2 -> 0.25 | J16: =MAX(0,MAX(K7)-G16) -> 17.666667 | K16: =J16+H16 -> 21.833333 | L16: =M16-H16 -> 40.833333 | M16: =MIN(L17+G17) -> 45 | N16: =L16-J16 -> 23.166667 | O16: =IF(ABS(N16)<0.005,"Găng","")
A17: M | B17: =PERT!B21 -> Kiểm thử hệ thống và sửa lỗi | C17: J, K, H, L | D17: =PERT!E21 -> 8 | E17: =PERT!F21 -> 12 | F17: =PERT!G21 -> 18 | G17: 5 | H17: =(D17+4*E17+F17)/6 -> 12.333333 | I17: =((F17-D17)/6)^2 -> 2.7777778 | J17: =MAX(0,MAX(K14,K15,K12,K16)-G17) -> 40 | K17: =J17+H17 -> 52.333333 | L17: =M17-H17 -> 40 | M17: =MIN(L18+G18) -> 52.333333 | N17: =L17-J17 -> 0 | O17: =IF(ABS(N17)<0.005,"Găng","") -> Găng | P17: Fast-tracking: kiểm thử theo từng module xong trước, chồng 5 ngày cuối giai đoạn phát triển
A18: N | B18: =PERT!B22 -> Kiểm thử chấp nhận (UAT) và nghiệm thu | C18: M | D18: =PERT!E22 -> 3 | E18: =PERT!F22 -> 5 | F18: =PERT!G22 -> 8 | G18: 0 | H18: =(D18+4*E18+F18)/6 -> 5.1666667 | I18: =((F18-D18)/6)^2 -> 0.69444444 | J18: =MAX(0,MAX(K17)-G18) -> 52.333333 | K18: =J18+H18 -> 57.5 | L18: =M18-H18 -> 52.333333 | M18: =MIN(L19+G19) -> 57.5 | N18: =L18-J18 -> 0 | O18: =IF(ABS(N18)<0.005,"Găng","") -> Găng
A19: O | B19: =PERT!B23 -> Go-live, đào tạo người dùng | C19: N | D19: =PERT!E23 -> 3 | E19: =PERT!F23 -> 4 | F19: =PERT!G23 -> 7 | G19: 0 | H19: =(D19+4*E19+F19)/6 -> 4.3333333 | I19: =((F19-D19)/6)^2 -> 0.44444444 | J19: =MAX(0,MAX(K18)-G19) -> 57.5 | K19: =J19+H19 -> 61.833333 | L19: =M19-H19 -> 57.5 | M19: =$C$22 -> 61.833333 | N19: =L19-J19 -> 0 | O19: =IF(ABS(N19)<0.005,"Găng","") -> Găng
A21: KẾT QUẢ SAU KHI NÉN
A22: Thời gian dự án T mới (ngày làm việc) | C22: =MAX(K5:K19) -> 61.833333
A23: Đường găng mới | C23: =LEFT(IF(O5="Găng","A → ","")&IF(O6="Găng","B → ","")&IF(O7="Găng","C → ","")&IF(O8="Găng","D → ","")&IF(O9="Găng","E → ","")&IF(O10="Găng","F → ","")&IF(O11="Găng","G → ","")&IF(O12="Găng","H → ","")&IF(O13="Găng","I → ","")&IF(O14="Găng","J → ","")&IF(O15="Găng","K → ","")&IF(O16="Găng","L → ","")&IF(O17="Găng","M → ","")&IF(O18="Găng","N → ","")&IF(O19="Găng","O → ",""),LEN(IF(O5="Găng","A → ","")&IF(O6="Găng","B → ","")&IF(O7="Găng","C → ","")&IF(O8="Găng","D → ","")&IF(O9="Găng","E → ","")&IF(O10="Găng","F → ","")&IF(O11="Găng","G → ","")&IF(O12="Găng","H → ","")&IF(O13="Găng","I → ","")&IF(O14="Găng","J → ","")&IF(O15="Găng","K → ","")&IF(O16="Găng","L → ","")&IF(O17="Găng","M → ","")&IF(O18="Găng","N → ","")&IF(O19="Găng","O → ",""))-3) -> A → B → C → D → F → G → K → M → N → O
A24: Độ lệch chuẩn đường găng σ | C24: =SQRT(SUMIF(O5:O19,"Găng",I5:I19)) -> 3.3870669
A25: Số ngày làm việc tới hạn chót | C25: =PERT!C5 -> 64
A26: Dự trữ so với hạn chót (ngày) | C26: =C25-C22 -> 2.1666667
A27: Xác suất kịp hạn P(Z) | C27: =NORMSDIST((C25-C22)/C24) -> 0.73881233
A28: Ngày kết thúc dự kiến | C28: =WORKDAY(PERT!C3,ROUNDUP(C22,0)-1) -> 46385
A29: T lịch gốc (sheet PERT) / số ngày rút ngắn | C29: =PERT!$C$26 -> 75.333333 | D29: =C29-C22 -> 13.5

Sheet RuiRo
A1: SỔ ĐĂNG KÝ RỦI RO (RISK REGISTER) – sắp theo điểm giảm dần
A2: Mô tả theo cấu trúc Nguyên nhân – Sự kiện – Hậu quả. XS, TĐ thang 1–5; Điểm = XS × TĐ; ≥15 Cao, 8–14 Trung bình, <8 Thấp.
A4: ID | B4: Nguyên nhân | C4: Sự kiện rủi ro | D4: Hậu quả | E4: Nhóm | F4: XS (1–5) | G4: TĐ (1–5) | H4: Điểm | I4: Mức | J4: Chiến lược | K4: Hành động ứng phó | L4: Người phụ trách | M4: Nguồn
A5: R01 | B5: Phần mềm bán hàng hiện tại của nhà thuốc chưa rõ nhà cung cấp, có thể không có API hoặc không cho xuất dữ liệu tự động | C5: Không đồng bộ được dữ liệu bán hàng vào PharmaDash đúng hạn | D5: Dashboard không có số liệu thật, trễ go-live, mục tiêu "dữ liệu trễ ≤ 1 phút" không đạt | E5: Bên ngoài / Kỹ thuật | F5: 4 | G5: 5 | H5: =F5*G5 -> 20 | I5: =IF(H5>=15,"Cao",IF(H5>=8,"Trung bình","Thấp")) -> Cao | J5: Giảm | K5: Khảo sát phần mềm bán hàng ngay tuần 1; làm việc với nhà cung cấp phần mềm; chuẩn bị phương án dự phòng nhập file Excel xuất từ phần mềm bán hàng theo lịch (mỗi 15 phút / cuối ca) | L5: BE + BA | M5: AI gợi ý
A6: R02 | B6: Ước lượng PERT cho thấy đường găng dài hơn số ngày làm việc tới hạn chót 31/12 | C6: Dự án không kịp go-live trước hạn | D6: Không kịp dùng cho đợt kiểm kê cuối năm và cao điểm Tết, phát sinh chi phí kéo dài | E6: Lịch trình | F6: 4 | G6: 4 | H6: =F6*G6 -> 16 | I6: =IF(H6>=15,"Cao",IF(H6>=8,"Trung bình","Thấp")) -> Cao | J6: Giảm | K6: Nén lịch bằng fast-tracking (làm song song FE/BE, kiểm thử theo từng module) và/hoặc crashing (bổ sung nhân lực bán thời gian); cắt tính năng "Có thể có" | L6: PM | M6: AI gợi ý
A7: R03 | B7: Chủ nhà thuốc xem demo cuối mỗi tháng và thường phát sinh ý tưởng mới | C7: Yêu cầu thay đổi, phạm vi phình ra (scope creep) | D7: Tăng khối lượng công việc, trễ tiến độ, vượt ngân sách | E7: Khách hàng / Yêu cầu | F7: 4 | G7: 4 | H7: =F7*G7 -> 16 | I7: =IF(H7>=15,"Cao",IF(H7>=8,"Trung bình","Thấp")) -> Cao | J7: Tránh | K7: Thống nhất phạm vi trong Charter/SRS; quy trình kiểm soát thay đổi (Change Request) có đánh giá tác động thời gian – chi phí; đưa yêu cầu mới vào giai đoạn 2 | L7: PM | M7: AI gợi ý
A8: R04 | B8: Dữ liệu cũ quản lý bằng Excel: mã thuốc trùng, thiếu số lô, thiếu hạn dùng, sai đơn vị tính | C8: Chuyển đổi dữ liệu sai hoặc thiếu | D8: Cảnh báo hạn dùng và tồn kho sai, người dùng mất niềm tin vào hệ thống | E8: Kỹ thuật / Dữ liệu | F8: 4 | G8: 4 | H8: =F8*G8 -> 16 | I8: =IF(H8>=15,"Cao",IF(H8>=8,"Trung bình","Thấp")) -> Cao | J8: Giảm | K8: Viết script kiểm tra chất lượng dữ liệu; làm sạch dữ liệu cùng dược sĩ phụ trách kho; đối soát tồn kho thực tế trước go-live | L8: BE + BA | M8: AI gợi ý
A9: R05 | B9: Chỉ có 1 lập trình viên backend với khối lượng khoảng 460 giờ trên tổng khoảng 520 giờ khả dụng | C9: Lập trình viên backend quá tải, ốm hoặc nghỉ việc | D9: API trễ, kéo theo frontend và kiểm thử trễ (nằm trên đường gần găng) | E9: Con người | F9: 3 | G9: 5 | H9: =F9*G9 -> 15 | I9: =IF(H9>=15,"Cao",IF(H9>=8,"Trung bình","Thấp")) -> Cao | J9: Giảm | K9: Lập trình viên frontend hỗ trợ API đơn giản; code review chéo; tài liệu hóa API; theo dõi khối lượng hằng tuần | L9: PM | M9: AI gợi ý
A10: R11 | B10: Thành viên có việc gia đình đột xuất (đồ án trước của nhóm từng bị trễ vì lý do này) | C10: Một thành viên phải nghỉ vài ngày đến 1 tuần, không báo trước được | D10: Gói việc của người đó bị dừng; nếu là việc trên đường găng (BE, FE) thì cả dự án trễ theo | E10: Con người | F10: 3 | G10: 4 | H10: =IF(OR(F10="",G10=""),"",F10*G10) -> 12 | I10: =IF(H10="","",IF(H10>=15,"Cao",IF(H10>=8,"Trung bình","Thấp"))) -> Trung bình | J10: Giảm | K10: Mỗi người có 1 "người đỡ" (buddy) nắm việc của mình; cập nhật tiến độ hằng ngày trên nhóm chat; đẩy code lên GitHub cuối mỗi ngày để người khác làm tiếp được | L10: PM | M10: Nhóm bổ sung
A11: R06 | B11: Hệ thống chứa thông tin khách hàng (họ tên, SĐT, lịch sử mua thuốc) và giá nhập, lợi nhuận | C11: Lộ dữ liệu do phân quyền sai hoặc tấn công | D11: Vi phạm quy định bảo vệ dữ liệu cá nhân, mất uy tín, rò rỉ bí mật kinh doanh | E11: Bảo mật / Pháp lý | F11: 2 | G11: 5 | H11: =F11*G11 -> 10 | I11: =IF(H11>=15,"Cao",IF(H11>=8,"Trung bình","Thấp")) -> Trung bình | J11: Giảm | K11: Phân quyền kiểm tra ở máy chủ; HTTPS; mã hóa mật khẩu; kiểm thử phân quyền riêng; sao lưu có mã hóa | L11: BE + QA | M11: AI gợi ý
A12: R07 | B12: Nhân viên quen thao tác giấy và Excel, ít thời gian học phần mềm mới | C12: Người dùng không sử dụng hoặc dùng sai hệ thống | D12: Dữ liệu không được cập nhật, hệ thống không mang lại giá trị | E12: Con người / Khách hàng | F12: 3 | G12: 3 | H12: =F12*G12 -> 9 | I12: =IF(H12>=15,"Cao",IF(H12>=8,"Trung bình","Thấp")) -> Trung bình | J12: Giảm | K12: Giao diện đơn giản; đào tạo tại từng chi nhánh; chọn 1 người dùng chủ chốt (key user) mỗi chi nhánh | L12: BA | M12: AI gợi ý
A13: R08 | B13: Dữ liệu 2 năm bán hàng (hàng trăm nghìn dòng) và truy vấn thống kê phức tạp | C13: Dashboard phản hồi chậm hơn 2 giây | D13: Trải nghiệm kém, không đạt yêu cầu phi chức năng | E13: Kỹ thuật | F13: 3 | G13: 3 | H13: =F13*G13 -> 9 | I13: =IF(H13>=15,"Cao",IF(H13>=8,"Trung bình","Thấp")) -> Trung bình | J13: Giảm | K13: Tạo chỉ mục CSDL, bảng tổng hợp theo ngày; kiểm thử hiệu năng với dữ liệu thật từ sớm | L13: BE | M13: AI gợi ý
A14: R12 | B14: Nhóm đọc yêu cầu theo cách hiểu của mình, không xác nhận lại (đồ án trước nhóm từng hiểu sai yêu cầu của giảng viên và phải làm lại) | C14: Hiểu sai một yêu cầu của khách hàng (ví dụ cách tính lợi nhuận, quy tắc cảnh báo hạn dùng), phát hiện muộn khi demo hoặc UAT | D14: Phải làm lại (rework) chức năng đã xong, tốn thêm giờ công, ăn vào 2 ngày dự trữ của lịch đã nén | E14: Yêu cầu | F14: 3 | G14: 3 | H14: =IF(OR(F14="",G14=""),"",F14*G14) -> 9 | I14: =IF(H14="","",IF(H14>=15,"Cao",IF(H14>=8,"Trung bình","Thấp"))) -> Trung bình | J14: Giảm | K14: Sau mỗi buổi làm việc với khách hàng, BA gửi lại biên bản tóm tắt yêu cầu để khách xác nhận; viết tiêu chí chấp nhận cho từng FR trước khi code; demo bản nháp sớm (mockup) thay vì chờ demo cuối tháng | L14: BA | M14: Nhóm bổ sung
A15: R09 | B15: Quy định ngành dược (GPP, thuốc kê đơn) có thể yêu cầu lưu trữ hoặc báo cáo đặc thù chưa nêu trong yêu cầu | C15: Phát sinh yêu cầu bắt buộc muộn | D15: Phải làm thêm chức năng, trễ tiến độ | E15: Khách hàng / Pháp lý | F15: 2 | G15: 4 | H15: =F15*G15 -> 8 | I15: =IF(H15>=15,"Cao",IF(H15>=8,"Trung bình","Thấp")) -> Trung bình | J15: Giảm | K15: Hỏi rõ với chủ nhà thuốc và dược sĩ phụ trách chuyên môn ngay khi khảo sát; ghi nhận vào SRS | L15: BA | M15: AI gợi ý
A16: R10 | B16: Hệ thống chạy trên máy chủ thuê ngoài, mạng Internet tại chi nhánh không ổn định | C16: Máy chủ hoặc mạng gặp sự cố | D16: Không truy cập được dashboard trong giờ bán hàng | E16: Bên ngoài / Hạ tầng | F16: 2 | G16: 3 | H16: =F16*G16 -> 6 | I16: =IF(H16>=15,"Cao",IF(H16>=8,"Trung bình","Thấp")) -> Thấp | J16: Chuyển giao | K16: Chọn nhà cung cấp VPS có cam kết SLA 99,9% trong hợp đồng; sao lưu hằng ngày; hướng dẫn phương án xử lý sự cố | L16: BE | M16: AI gợi ý

Sheet MaTran
A1: MA TRẬN XÁC SUẤT × TÁC ĐỘNG (5×5) – tự cập nhật từ sheet RuiRo
C3: TÁC ĐỘNG →
C4: 1 | D4: 2 | E4: 3 | F4: 4 | G4: 5
A5: XÁC SUẤT ↓ | B5: 5 | C5: =TRIM(IF(AND(RuiRo!$F$5=5,RuiRo!$G$5=1),RuiRo!$A$5&" ","")&IF(AND(RuiRo!$F$6=5,RuiRo!$G$6=1),RuiRo!$A$6&" ","")&IF(AND(RuiRo!$F$7=5,RuiRo!$G$7=1),RuiRo!$A$7&" ","")&IF(AND(RuiRo!$F$8=5,RuiRo!$G$8=1),RuiRo!$A$8&" ","")&IF(AND(RuiRo!$F$9=5,RuiRo!$G$9=1),RuiRo!$A$9&" ","")&IF(AND(RuiRo!$F$10=5,RuiRo!$G$10=1),RuiRo!$A$10&" ","")&IF(AND(RuiRo!$F$11=5,RuiRo!$G$11=1),RuiRo!$A$11&" ","")&IF(AND(RuiRo!$F$12=5,RuiRo!$G$12=1),RuiRo!$A$12&" ","")&IF(AND(RuiRo!$F$13=5,RuiRo!$G$13=1),RuiRo!$A$13&" ","")&IF(AND(RuiRo!$F$14=5,RuiRo!$G$14=1),RuiRo!$A$14&" ","")&IF(AND(RuiRo!$F$15=5,RuiRo!$G$15=1),RuiRo!$A$15&" ","")&IF(AND(RuiRo!$F$16=5,RuiRo!$G$16=1),RuiRo!$A$16&" ","")) | D5: =TRIM(IF(AND(RuiRo!$F$5=5,RuiRo!$G$5=2),RuiRo!$A$5&" ","")&IF(AND(RuiRo!$F$6=5,RuiRo!$G$6=2),RuiRo!$A$6&" ","")&IF(AND(RuiRo!$F$7=5,RuiRo!$G$7=2),RuiRo!$A$7&" ","")&IF(AND(RuiRo!$F$8=5,RuiRo!$G$8=2),RuiRo!$A$8&" ","")&IF(AND(RuiRo!$F$9=5,RuiRo!$G$9=2),RuiRo!$A$9&" ","")&IF(AND(RuiRo!$F$10=5,RuiRo!$G$10=2),RuiRo!$A$10&" ","")&IF(AND(RuiRo!$F$11=5,RuiRo!$G$11=2),RuiRo!$A$11&" ","")&IF(AND(RuiRo!$F$12=5,RuiRo!$G$12=2),RuiRo!$A$12&" ","")&IF(AND(RuiRo!$F$13=5,RuiRo!$G$13=2),RuiRo!$A$13&" ","")&IF(AND(RuiRo!$F$14=5,RuiRo!$G$14=2),RuiRo!$A$14&" ","")&IF(AND(RuiRo!$F$15=5,RuiRo!$G$15=2),RuiRo!$A$15&" ","")&IF(AND(RuiRo!$F$16=5,RuiRo!$G$16=2),RuiRo!$A$16&" ","")) | E5: =TRIM(IF(AND(RuiRo!$F$5=5,RuiRo!$G$5=3),RuiRo!$A$5&" ","")&IF(AND(RuiRo!$F$6=5,RuiRo!$G$6=3),RuiRo!$A$6&" ","")&IF(AND(RuiRo!$F$7=5,RuiRo!$G$7=3),RuiRo!$A$7&" ","")&IF(AND(RuiRo!$F$8=5,RuiRo!$G$8=3),RuiRo!$A$8&" ","")&IF(AND(RuiRo!$F$9=5,RuiRo!$G$9=3),RuiRo!$A$9&" ","")&IF(AND(RuiRo!$F$10=5,RuiRo!$G$10=3),RuiRo!$A$10&" ","")&IF(AND(RuiRo!$F$11=5,RuiRo!$G$11=3),RuiRo!$A$11&" ","")&IF(AND(RuiRo!$F$12=5,RuiRo!$G$12=3),RuiRo!$A$12&" ","")&IF(AND(RuiRo!$F$13=5,RuiRo!$G$13=3),RuiRo!$A$13&" ","")&IF(AND(RuiRo!$F$14=5,RuiRo!$G$14=3),RuiRo!$A$14&" ","")&IF(AND(RuiRo!$F$15=5,RuiRo!$G$15=3),RuiRo!$A$15&" ","")&IF(AND(RuiRo!$F$16=5,RuiRo!$G$16=3),RuiRo!$A$16&" ","")) | F5: =TRIM(IF(AND(RuiRo!$F$5=5,RuiRo!$G$5=4),RuiRo!$A$5&" ","")&IF(AND(RuiRo!$F$6=5,RuiRo!$G$6=4),RuiRo!$A$6&" ","")&IF(AND(RuiRo!$F$7=5,RuiRo!$G$7=4),RuiRo!$A$7&" ","")&IF(AND(RuiRo!$F$8=5,RuiRo!$G$8=4),RuiRo!$A$8&" ","")&IF(AND(RuiRo!$F$9=5,RuiRo!$G$9=4),RuiRo!$A$9&" ","")&IF(AND(RuiRo!$F$10=5,RuiRo!$G$10=4),RuiRo!$A$10&" ","")&IF(AND(RuiRo!$F$11=5,RuiRo!$G$11=4),RuiRo!$A$11&" ","")&IF(AND(RuiRo!$F$12=5,RuiRo!$G$12=4),RuiRo!$A$12&" ","")&IF(AND(RuiRo!$F$13=5,RuiRo!$G$13=4),RuiRo!$A$13&" ","")&IF(AND(RuiRo!$F$14=5,RuiRo!$G$14=4),RuiRo!$A$14&" ","")&IF(AND(RuiRo!$F$15=5,RuiRo!$G$15=4),RuiRo!$A$15&" ","")&IF(AND(RuiRo!$F$16=5,RuiRo!$G$16=4),RuiRo!$A$16&" ","")) | G5: =TRIM(IF(AND(RuiRo!$F$5=5,RuiRo!$G$5=5),RuiRo!$A$5&" ","")&IF(AND(RuiRo!$F$6=5,RuiRo!$G$6=5),RuiRo!$A$6&" ","")&IF(AND(RuiRo!$F$7=5,RuiRo!$G$7=5),RuiRo!$A$7&" ","")&IF(AND(RuiRo!$F$8=5,RuiRo!$G$8=5),RuiRo!$A$8&" ","")&IF(AND(RuiRo!$F$9=5,RuiRo!$G$9=5),RuiRo!$A$9&" ","")&IF(AND(RuiRo!$F$10=5,RuiRo!$G$10=5),RuiRo!$A$10&" ","")&IF(AND(RuiRo!$F$11=5,RuiRo!$G$11=5),RuiRo!$A$11&" ","")&IF(AND(RuiRo!$F$12=5,RuiRo!$G$12=5),RuiRo!$A$12&" ","")&IF(AND(RuiRo!$F$13=5,RuiRo!$G$13=5),RuiRo!$A$13&" ","")&IF(AND(RuiRo!$F$14=5,RuiRo!$G$14=5),RuiRo!$A$14&" ","")&IF(AND(RuiRo!$F$15=5,RuiRo!$G$15=5),RuiRo!$A$15&" ","")&IF(AND(RuiRo!$F$16=5,RuiRo!$G$16=5),RuiRo!$A$16&" ",""))
B6: 4 | C6: =TRIM(IF(AND(RuiRo!$F$5=4,RuiRo!$G$5=1),RuiRo!$A$5&" ","")&IF(AND(RuiRo!$F$6=4,RuiRo!$G$6=1),RuiRo!$A$6&" ","")&IF(AND(RuiRo!$F$7=4,RuiRo!$G$7=1),RuiRo!$A$7&" ","")&IF(AND(RuiRo!$F$8=4,RuiRo!$G$8=1),RuiRo!$A$8&" ","")&IF(AND(RuiRo!$F$9=4,RuiRo!$G$9=1),RuiRo!$A$9&" ","")&IF(AND(RuiRo!$F$10=4,RuiRo!$G$10=1),RuiRo!$A$10&" ","")&IF(AND(RuiRo!$F$11=4,RuiRo!$G$11=1),RuiRo!$A$11&" ","")&IF(AND(RuiRo!$F$12=4,RuiRo!$G$12=1),RuiRo!$A$12&" ","")&IF(AND(RuiRo!$F$13=4,RuiRo!$G$13=1),RuiRo!$A$13&" ","")&IF(AND(RuiRo!$F$14=4,RuiRo!$G$14=1),RuiRo!$A$14&" ","")&IF(AND(RuiRo!$F$15=4,RuiRo!$G$15=1),RuiRo!$A$15&" ","")&IF(AND(RuiRo!$F$16=4,RuiRo!$G$16=1),RuiRo!$A$16&" ","")) | D6: =TRIM(IF(AND(RuiRo!$F$5=4,RuiRo!$G$5=2),RuiRo!$A$5&" ","")&IF(AND(RuiRo!$F$6=4,RuiRo!$G$6=2),RuiRo!$A$6&" ","")&IF(AND(RuiRo!$F$7=4,RuiRo!$G$7=2),RuiRo!$A$7&" ","")&IF(AND(RuiRo!$F$8=4,RuiRo!$G$8=2),RuiRo!$A$8&" ","")&IF(AND(RuiRo!$F$9=4,RuiRo!$G$9=2),RuiRo!$A$9&" ","")&IF(AND(RuiRo!$F$10=4,RuiRo!$G$10=2),RuiRo!$A$10&" ","")&IF(AND(RuiRo!$F$11=4,RuiRo!$G$11=2),RuiRo!$A$11&" ","")&IF(AND(RuiRo!$F$12=4,RuiRo!$G$12=2),RuiRo!$A$12&" ","")&IF(AND(RuiRo!$F$13=4,RuiRo!$G$13=2),RuiRo!$A$13&" ","")&IF(AND(RuiRo!$F$14=4,RuiRo!$G$14=2),RuiRo!$A$14&" ","")&IF(AND(RuiRo!$F$15=4,RuiRo!$G$15=2),RuiRo!$A$15&" ","")&IF(AND(RuiRo!$F$16=4,RuiRo!$G$16=2),RuiRo!$A$16&" ","")) | E6: =TRIM(IF(AND(RuiRo!$F$5=4,RuiRo!$G$5=3),RuiRo!$A$5&" ","")&IF(AND(RuiRo!$F$6=4,RuiRo!$G$6=3),RuiRo!$A$6&" ","")&IF(AND(RuiRo!$F$7=4,RuiRo!$G$7=3),RuiRo!$A$7&" ","")&IF(AND(RuiRo!$F$8=4,RuiRo!$G$8=3),RuiRo!$A$8&" ","")&IF(AND(RuiRo!$F$9=4,RuiRo!$G$9=3),RuiRo!$A$9&" ","")&IF(AND(RuiRo!$F$10=4,RuiRo!$G$10=3),RuiRo!$A$10&" ","")&IF(AND(RuiRo!$F$11=4,RuiRo!$G$11=3),RuiRo!$A$11&" ","")&IF(AND(RuiRo!$F$12=4,RuiRo!$G$12=3),RuiRo!$A$12&" ","")&IF(AND(RuiRo!$F$13=4,RuiRo!$G$13=3),RuiRo!$A$13&" ","")&IF(AND(RuiRo!$F$14=4,RuiRo!$G$14=3),RuiRo!$A$14&" ","")&IF(AND(RuiRo!$F$15=4,RuiRo!$G$15=3),RuiRo!$A$15&" ","")&IF(AND(RuiRo!$F$16=4,RuiRo!$G$16=3),RuiRo!$A$16&" ","")) | F6: =TRIM(IF(AND(RuiRo!$F$5=4,RuiRo!$G$5=4),RuiRo!$A$5&" ","")&IF(AND(RuiRo!$F$6=4,RuiRo!$G$6=4),RuiRo!$A$6&" ","")&IF(AND(RuiRo!$F$7=4,RuiRo!$G$7=4),RuiRo!$A$7&" ","")&IF(AND(RuiRo!$F$8=4,RuiRo!$G$8=4),RuiRo!$A$8&" ","")&IF(AND(RuiRo!$F$9=4,RuiRo!$G$9=4),RuiRo!$A$9&" ","")&IF(AND(RuiRo!$F$10=4,RuiRo!$G$10=4),RuiRo!$A$10&" ","")&IF(AND(RuiRo!$F$11=4,RuiRo!$G$11=4),RuiRo!$A$11&" ","")&IF(AND(RuiRo!$F$12=4,RuiRo!$G$12=4),RuiRo!$A$12&" ","")&IF(AND(RuiRo!$F$13=4,RuiRo!$G$13=4),RuiRo!$A$13&" ","")&IF(AND(RuiRo!$F$14=4,RuiRo!$G$14=4),RuiRo!$A$14&" ","")&IF(AND(RuiRo!$F$15=4,RuiRo!$G$15=4),RuiRo!$A$15&" ","")&IF(AND(RuiRo!$F$16=4,RuiRo!$G$16=4),RuiRo!$A$16&" ","")) -> R02 R03 R04 | G6: =TRIM(IF(AND(RuiRo!$F$5=4,RuiRo!$G$5=5),RuiRo!$A$5&" ","")&IF(AND(RuiRo!$F$6=4,RuiRo!$G$6=5),RuiRo!$A$6&" ","")&IF(AND(RuiRo!$F$7=4,RuiRo!$G$7=5),RuiRo!$A$7&" ","")&IF(AND(RuiRo!$F$8=4,RuiRo!$G$8=5),RuiRo!$A$8&" ","")&IF(AND(RuiRo!$F$9=4,RuiRo!$G$9=5),RuiRo!$A$9&" ","")&IF(AND(RuiRo!$F$10=4,RuiRo!$G$10=5),RuiRo!$A$10&" ","")&IF(AND(RuiRo!$F$11=4,RuiRo!$G$11=5),RuiRo!$A$11&" ","")&IF(AND(RuiRo!$F$12=4,RuiRo!$G$12=5),RuiRo!$A$12&" ","")&IF(AND(RuiRo!$F$13=4,RuiRo!$G$13=5),RuiRo!$A$13&" ","")&IF(AND(RuiRo!$F$14=4,RuiRo!$G$14=5),RuiRo!$A$14&" ","")&IF(AND(RuiRo!$F$15=4,RuiRo!$G$15=5),RuiRo!$A$15&" ","")&IF(AND(RuiRo!$F$16=4,RuiRo!$G$16=5),RuiRo!$A$16&" ","")) -> R01
B7: 3 | C7: =TRIM(IF(AND(RuiRo!$F$5=3,RuiRo!$G$5=1),RuiRo!$A$5&" ","")&IF(AND(RuiRo!$F$6=3,RuiRo!$G$6=1),RuiRo!$A$6&" ","")&IF(AND(RuiRo!$F$7=3,RuiRo!$G$7=1),RuiRo!$A$7&" ","")&IF(AND(RuiRo!$F$8=3,RuiRo!$G$8=1),RuiRo!$A$8&" ","")&IF(AND(RuiRo!$F$9=3,RuiRo!$G$9=1),RuiRo!$A$9&" ","")&IF(AND(RuiRo!$F$10=3,RuiRo!$G$10=1),RuiRo!$A$10&" ","")&IF(AND(RuiRo!$F$11=3,RuiRo!$G$11=1),RuiRo!$A$11&" ","")&IF(AND(RuiRo!$F$12=3,RuiRo!$G$12=1),RuiRo!$A$12&" ","")&IF(AND(RuiRo!$F$13=3,RuiRo!$G$13=1),RuiRo!$A$13&" ","")&IF(AND(RuiRo!$F$14=3,RuiRo!$G$14=1),RuiRo!$A$14&" ","")&IF(AND(RuiRo!$F$15=3,RuiRo!$G$15=1),RuiRo!$A$15&" ","")&IF(AND(RuiRo!$F$16=3,RuiRo!$G$16=1),RuiRo!$A$16&" ","")) | D7: =TRIM(IF(AND(RuiRo!$F$5=3,RuiRo!$G$5=2),RuiRo!$A$5&" ","")&IF(AND(RuiRo!$F$6=3,RuiRo!$G$6=2),RuiRo!$A$6&" ","")&IF(AND(RuiRo!$F$7=3,RuiRo!$G$7=2),RuiRo!$A$7&" ","")&IF(AND(RuiRo!$F$8=3,RuiRo!$G$8=2),RuiRo!$A$8&" ","")&IF(AND(RuiRo!$F$9=3,RuiRo!$G$9=2),RuiRo!$A$9&" ","")&IF(AND(RuiRo!$F$10=3,RuiRo!$G$10=2),RuiRo!$A$10&" ","")&IF(AND(RuiRo!$F$11=3,RuiRo!$G$11=2),RuiRo!$A$11&" ","")&IF(AND(RuiRo!$F$12=3,RuiRo!$G$12=2),RuiRo!$A$12&" ","")&IF(AND(RuiRo!$F$13=3,RuiRo!$G$13=2),RuiRo!$A$13&" ","")&IF(AND(RuiRo!$F$14=3,RuiRo!$G$14=2),RuiRo!$A$14&" ","")&IF(AND(RuiRo!$F$15=3,RuiRo!$G$15=2),RuiRo!$A$15&" ","")&IF(AND(RuiRo!$F$16=3,RuiRo!$G$16=2),RuiRo!$A$16&" ","")) | E7: =TRIM(IF(AND(RuiRo!$F$5=3,RuiRo!$G$5=3),RuiRo!$A$5&" ","")&IF(AND(RuiRo!$F$6=3,RuiRo!$G$6=3),RuiRo!$A$6&" ","")&IF(AND(RuiRo!$F$7=3,RuiRo!$G$7=3),RuiRo!$A$7&" ","")&IF(AND(RuiRo!$F$8=3,RuiRo!$G$8=3),RuiRo!$A$8&" ","")&IF(AND(RuiRo!$F$9=3,RuiRo!$G$9=3),RuiRo!$A$9&" ","")&IF(AND(RuiRo!$F$10=3,RuiRo!$G$10=3),RuiRo!$A$10&" ","")&IF(AND(RuiRo!$F$11=3,RuiRo!$G$11=3),RuiRo!$A$11&" ","")&IF(AND(RuiRo!$F$12=3,RuiRo!$G$12=3),RuiRo!$A$12&" ","")&IF(AND(RuiRo!$F$13=3,RuiRo!$G$13=3),RuiRo!$A$13&" ","")&IF(AND(RuiRo!$F$14=3,RuiRo!$G$14=3),RuiRo!$A$14&" ","")&IF(AND(RuiRo!$F$15=3,RuiRo!$G$15=3),RuiRo!$A$15&" ","")&IF(AND(RuiRo!$F$16=3,RuiRo!$G$16=3),RuiRo!$A$16&" ","")) -> R07 R08 R12 | F7: =TRIM(IF(AND(RuiRo!$F$5=3,RuiRo!$G$5=4),RuiRo!$A$5&" ","")&IF(AND(RuiRo!$F$6=3,RuiRo!$G$6=4),RuiRo!$A$6&" ","")&IF(AND(RuiRo!$F$7=3,RuiRo!$G$7=4),RuiRo!$A$7&" ","")&IF(AND(RuiRo!$F$8=3,RuiRo!$G$8=4),RuiRo!$A$8&" ","")&IF(AND(RuiRo!$F$9=3,RuiRo!$G$9=4),RuiRo!$A$9&" ","")&IF(AND(RuiRo!$F$10=3,RuiRo!$G$10=4),RuiRo!$A$10&" ","")&IF(AND(RuiRo!$F$11=3,RuiRo!$G$11=4),RuiRo!$A$11&" ","")&IF(AND(RuiRo!$F$12=3,RuiRo!$G$12=4),RuiRo!$A$12&" ","")&IF(AND(RuiRo!$F$13=3,RuiRo!$G$13=4),RuiRo!$A$13&" ","")&IF(AND(RuiRo!$F$14=3,RuiRo!$G$14=4),RuiRo!$A$14&" ","")&IF(AND(RuiRo!$F$15=3,RuiRo!$G$15=4),RuiRo!$A$15&" ","")&IF(AND(RuiRo!$F$16=3,RuiRo!$G$16=4),RuiRo!$A$16&" ","")) -> R11 | G7: =TRIM(IF(AND(RuiRo!$F$5=3,RuiRo!$G$5=5),RuiRo!$A$5&" ","")&IF(AND(RuiRo!$F$6=3,RuiRo!$G$6=5),RuiRo!$A$6&" ","")&IF(AND(RuiRo!$F$7=3,RuiRo!$G$7=5),RuiRo!$A$7&" ","")&IF(AND(RuiRo!$F$8=3,RuiRo!$G$8=5),RuiRo!$A$8&" ","")&IF(AND(RuiRo!$F$9=3,RuiRo!$G$9=5),RuiRo!$A$9&" ","")&IF(AND(RuiRo!$F$10=3,RuiRo!$G$10=5),RuiRo!$A$10&" ","")&IF(AND(RuiRo!$F$11=3,RuiRo!$G$11=5),RuiRo!$A$11&" ","")&IF(AND(RuiRo!$F$12=3,RuiRo!$G$12=5),RuiRo!$A$12&" ","")&IF(AND(RuiRo!$F$13=3,RuiRo!$G$13=5),RuiRo!$A$13&" ","")&IF(AND(RuiRo!$F$14=3,RuiRo!$G$14=5),RuiRo!$A$14&" ","")&IF(AND(RuiRo!$F$15=3,RuiRo!$G$15=5),RuiRo!$A$15&" ","")&IF(AND(RuiRo!$F$16=3,RuiRo!$G$16=5),RuiRo!$A$16&" ","")) -> R05
